Workbook
Name AuditCost: ASSUMPTIONS!$B$8
Name AuditRate: ASSUMPTIONS!$B$2
Name GrowthRate: ASSUMPTIONS!$B$13
Name Overhead: ASSUMPTIONS!$B$12
Name RateIncrease: ASSUMPTIONS!$B$15
Name TargetReal: ASSUMPTIONS!$B$5
Name TargetUtil: ASSUMPTIONS!$B$4
Name TaxCost: ASSUMPTIONS!$B$11
Name TaxRate: ASSUMPTIONS!$B$3

Sheet ACTUALS
A1: Year | B1: Service Line | C1: Available Hours | D1: Billable Hours | E1: Standard_rate | F1: Revenue_Billed | G1: Cost_of_Delivery | H1: Engagement Margin | I1: Utilization_Pct | J1: Realization_Pct | K1: Cost per hour | L1: Overhead allocation | M1: AVG REV Growth
A2: 2019 | B2: Audit | C2: 85000 | D2: 63750 | E2: 195 | F2: 11219625 | G2: 10455000 | H2: =F2-G2 -> 764625 | I2: =D2/C2 -> 0.75 | J2: =F2/(D2*E2) -> 0.90253394 | K2: =G2/D2 -> 164 | L2: =G2/F2 -> 0.93184933
A3: 2020 | B3: Audit | C3: 82000 | D3: 59050 | E3: 198 | F3: 10498302 | G3: 9880000 | H3: =F3-G3 -> 618302 | I3: =D3/C3 -> 0.72012195 | J3: =F3/(D3*E3) -> 0.8979124 | K3: =G3/D3 -> 167.31583 | L3: =G3/F3 -> 0.94110457 | M3: =((F3-F2)/F2) -> -0.064291186
A4: 2021 | B4: Audit | C4: 88000 | D4: 67760 | E4: 202 | F4: 12322387 | G4: 11450000 | H4: =F4-G4 -> 872387 | I4: =D4/C4 -> 0.77 | J4: =F4/(D4*E4) -> 0.9002644 | K4: =G4/D4 -> 168.97875 | L4: =G4/F4 -> 0.92920308 | M4: =((F4-F3)/F3) -> 0.17375048
A5: 2022 | B5: Audit | C5: 92000 | D5: 72540 | E5: 208 | F5: 13596595 | G5: 12480000 | H5: =F5-G5 -> 1116595 | I5: =D5/C5 -> 0.78847826 | J5: =F5/(D5*E5) -> 0.90113379 | K5: =G5/D5 -> 172.04301 | L5: =G5/F5 -> 0.91787687 | M5: =((F5-F4)/F4) -> 0.10340594
A6: 2023 | B6: Audit | C6: 96000 | D6: 77760 | E6: 215 | F6: 15043680 | G6: 13750000 | H6: =F6-G6 -> 1293680 | I6: =D6/C6 -> 0.81 | J6: =F6/(D6*E6) -> 0.89982773 | K6: =G6/D6 -> 176.82613 | L6: =G6/F6 -> 0.91400508 | M6: =((F6-F5)/F5) -> 0.10642996
A7: 2024 | B7: Audit | C7: 100000 | D7: 82000 | E7: 220 | F7: 16244400 | G7: 14800000 | H7: =F7-G7 -> 1444400 | I7: =D7/C7 -> 0.82 | J7: =F7/(D7*E7) -> 0.90046563 | K7: =G7/D7 -> 180.4878 | L7: =G7/F7 -> 0.9110832 | M7: =((F7-F6)/F6) -> 0.079815577
A8: 2019 | B8: Tax | C8: 62000 | D8: 49600 | E8: 225 | F8: 10066800 | G8: 9275000 | H8: =F8-G8 -> 791800 | I8: =D8/C8 -> 0.8 | J8: =F8/(D8*E8) -> 0.90204301 | K8: =G8/D8 -> 186.99597 | L8: =G8/F8 -> 0.92134541
A9: 2020 | B9: Tax | C9: 60000 | D9: 46200 | E9: 228 | F9: 9471744 | G9: 8920000 | H9: =F9-G9 -> 551744 | I9: =D9/C9 -> 0.77 | J9: =F9/(D9*E9) -> 0.89919344 | K9: =G9/D9 -> 193.07359 | L9: =G9/F9 -> 0.94174843 | M9: =((F9-F8)/F8) -> -0.05911074
A10: 2021 | B10: Tax | C10: 64000 | D10: 51200 | E10: 232 | F10: 10692864 | G10: 9850000 | H10: =F10-G10 -> 842864 | I10: =D10/C10 -> 0.8 | J10: =F10/(D10*E10) -> 0.90019397 | K10: =G10/D10 -> 192.38281 | L10: =G10/F10 -> 0.92117509 | M10: =((F10-F9)/F9) -> 0.1289224
A11: 2022 | B11: Tax | C11: 67000 | D11: 54270 | E11: 238 | F11: 11630527 | G11: 10620000 | H11: =F11-G11 -> 1010527 | I11: =D11/C11 -> 0.81 | J11: =F11/(D11*E11) -> 0.90045625 | K11: =G11/D11 -> 195.68823 | L11: =G11/F11 -> 0.91311426 | M11: =((F11-F10)/F10) -> 0.087690538
A12: 2023 | B12: Tax | C12: 70000 | D12: 57400 | E12: 245 | F12: 12657870 | G12: 11580000 | H12: =F12-G12 -> 1077870 | I12: =D12/C12 -> 0.82 | J12: =F12/(D12*E12) -> 0.9000832 | K12: =G12/D12 -> 201.74216 | L12: =G12/F12 -> 0.91484586 | M12: =((F12-F11)/F11) -> 0.088331595
A13: 2024 | B13: Tax | C13: 74000 | D13: 61420 | E13: 252 | F13: 13948675 | G13: 12650000 | H13: =F13-G13 -> 1298675 | I13: =D13/C13 -> 0.83 | J13: =F13/(D13*E13) -> 0.90120295 | K13: =G13/D13 -> 205.95897 | L13: =G13/F13 -> 0.90689617 | M13: =((F13-F12)/F12) -> 0.10197648
A14: 2019 | B14: Consulting | C14: 45000 | D14: 34650 | E14: 285 | F14: 8926898 | G14: 8250000 | H14: =F14-G14 -> 676898 | I14: =D14/C14 -> 0.77 | J14: =F14/(D14*E14) -> 0.90396679 | K14: =G14/D14 -> 238.09524 | L14: =G14/F14 -> 0.92417321
A15: 2020 | B15: Consulting | C15: 43000 | D15: 31820 | E15: 290 | F15: 8313228 | G15: 7780000 | H15: =F15-G15 -> 533228 | I15: =D15/C15 -> 0.74 | J15: =F15/(D15*E15) -> 0.90088949 | K15: =G15/D15 -> 244.50031 | L15: =G15/F15 -> 0.93585789 | M15: =((F15-F14)/F14) -> -0.068743924
A16: 2021 | B16: Consulting | C16: 48000 | D16: 37440 | E16: 295 | F16: 9954144 | G16: 9120000 | H16: =F16-G16 -> 834144 | I16: =D16/C16 -> 0.78 | J16: =F16/(D16*E16) -> 0.90125163 | K16: =G16/D16 -> 243.58974 | L16: =G16/F16 -> 0.91620133 | M16: =((F16-F15)/F15) -> 0.19738614
A17: 2022 | B17: Consulting | C17: 52000 | D17: 41600 | E17: 302 | F17: 11335168 | G17: 10280000 | H17: =F17-G17 -> 1055168 | I17: =D17/C17 -> 0.8 | J17: =F17/(D17*E17) -> 0.90225166 | K17: =G17/D17 -> 247.11538 | L17: =G17/F17 -> 0.90691201 | M17: =((F17-F16)/F16) -> 0.1387386
A18: 2023 | B18: Consulting | C18: 56000 | D18: 45920 | E18: 310 | F18: 12824038 | G18: 11580000 | H18: =F18-G18 -> 1244038 | I18: =D18/C18 -> 0.82 | J18: =F18/(D18*E18) -> 0.90086813 | K18: =G18/D18 -> 252.1777 | L18: =G18/F18 -> 0.90299171 | M18: =((F18-F17)/F17) -> 0.13134962
A19: 2024 | B19: Consulting | C19: 60000 | D19: 50400 | E19: 318 | F19: 14414976 | G19: 12850000 | H19: =F19-G19 -> 1564976 | I19: =D19/C19 -> 0.84 | J19: =F19/(D19*E19) -> 0.89940701 | K19: =G19/D19 -> 254.96032 | L19: =G19/F19 -> 0.89143402 | M19: =((F19-F18)/F18) -> 0.12405905
A20: 2019 | B20: Advisory | C20: 38000 | D20: 28880 | E20: 265 | F20: 6886208 | G20: 6420000 | H20: =F20-G20 -> 466208 | I20: =D20/C20 -> 0.76 | J20: =F20/(D20*E20) -> 0.89978153 | K20: =G20/D20 -> 222.29917 | L20: =G20/F20 -> 0.9322983
A21: 2020 | B21: Advisory | C21: 36000 | D21: 26280 | E21: 268 | F21: 6330758 | G21: 5980000 | H21: =F21-G21 -> 350758 | I21: =D21/C21 -> 0.73 | J21: =F21/(D21*E21) -> 0.89886725 | K21: =G21/D21 -> 227.54947 | L21: =G21/F21 -> 0.94459463 | M21: =((F21-F20)/F20) -> -0.080661229
A22: 2021 | B22: Advisory | C22: 40000 | D22: 31200 | E22: 272 | F22: 7637760 | G22: 7080000 | H22: =F22-G22 -> 557760 | I22: =D22/C22 -> 0.78 | J22: =F22/(D22*E22) -> 0.9 | K22: =G22/D22 -> 226.92308 | L22: =G22/F22 -> 0.92697335 | M22: =((F22-F21)/F21) -> 0.20645269
A23: 2022 | B23: Advisory | C23: 43000 | D23: 34400 | E23: 278 | F23: 8592704 | G23: 7920000 | H23: =F23-G23 -> 672704 | I23: =D23/C23 -> 0.8 | J23: =F23/(D23*E23) -> 0.89851765 | K23: =G23/D23 -> 230.23256 | L23: =G23/F23 -> 0.92171219 | M23: =((F23-F22)/F22) -> 0.12502933
A24: 2023 | B24: Advisory | C24: 46000 | D24: 37720 | E24: 285 | F24: 9687492 | G24: 8850000 | H24: =F24-G24 -> 837492 | I24: =D24/C24 -> 0.82 | J24: =F24/(D24*E24) -> 0.90114528 | K24: =G24/D24 -> 234.62354 | L24: =G24/F24 -> 0.91354914 | M24: =((F24-F23)/F23) -> 0.12740902
A25: 2024 | B25: Advisory | C25: 50000 | D25: 41500 | E25: 292 | F25: 10905480 | G25: 9780000 | H25: =F25-G25 -> 1125480 | I25: =D25/C25 -> 0.83 | J25: =F25/(D25*E25) -> 0.89994058 | K25: =G25/D25 -> 235.66265 | L25: =G25/F25 -> 0.89679684 | M25: =((F25-F24)/F24) -> 0.1257279
A27: Year Totals | B27: Available Hours | C27: Billable Hours | D27: Standard_rate | E27: Revenue_Billed | F27: Cost_of_Delivery | G27: Engagement Margin | H27: Utilization_Pct | I27: Realization_Pct | J27: Cost per hour | K27: Overhead allocation | L27: AVG REV Growth
A28: 2019 | B28: =SUMIF($A$2:$A$25,2019,C$2:C$25) -> 230000 | C28: =SUMIF($A$2:$A$25,2019,D$2:D$25) -> 176880 | D28: =E28/C28 -> 209.74407 | E28: =SUMIF($A$2:$A$25,2019,F$2:F$25) -> 37099531 | F28: =SUMIF($A$2:$A$25,2019,G$2:G$25) -> 34400000 | G28: =E28-F28 -> 2699531 | H28: =C28/B28 -> 0.76904348 | I28: - | J28: =F28/C28 -> 194.48213 | K28: =F28/E28 -> 0.92723544
A29: 2020 | B29: =SUMIF($A$2:$A$25,2020,C$2:C$25) -> 221000 | C29: =SUMIF($A$2:$A$25,2020,D$2:D$25) -> 163350 | D29: =E29/C29 -> 211.90102 | E29: =SUMIF($A$2:$A$25,2020,F$2:F$25) -> 34614032 | F29: =SUMIF($A$2:$A$25,2020,G$2:G$25) -> 32560000 | G29: =E29-F29 -> 2054032 | H29: =C29/B29 -> 0.73914027 | I29: - | J29: =F29/C29 -> 199.3266 | K29: =F29/E29 -> 0.94065898 | L29: =((E29-E28)/E28) -> -0.066995429
A30: 2021 | B30: =SUMIF($A$2:$A$25,2021,C$2:C$25) -> 240000 | C30: =SUMIF($A$2:$A$25,2021,D$2:D$25) -> 187600 | D30: =E30/C30 -> 216.45605 | E30: =SUMIF($A$2:$A$25,2021,F$2:F$25) -> 40607155 | F30: =SUMIF($A$2:$A$25,2021,G$2:G$25) -> 37500000 | G30: =E30-F30 -> 3107155 | H30: =C30/B30 -> 0.78166667 | I30: - | J30: =F30/C30 -> 199.89339 | K30: =F30/E30 -> 0.92348257 | L30: =((E30-E29)/E29) -> 0.17314143
A31: 2022 | B31: =SUMIF($A$2:$A$25,2022,C$2:C$25) -> 254000 | C31: =SUMIF($A$2:$A$25,2022,D$2:D$25) -> 202810 | D31: =E31/C31 -> 222.64678 | E31: =SUMIF($A$2:$A$25,2022,F$2:F$25) -> 45154994 | F31: =SUMIF($A$2:$A$25,2022,G$2:G$25) -> 41300000 | G31: =E31-F31 -> 3854994 | H31: =C31/B31 -> 0.79846457 | I31: - | J31: =F31/C31 -> 203.63887 | K31: =F31/E31 -> 0.91462752 | L31: =((E31-E30)/E30) -> 0.111996
A32: 2023 | B32: =SUMIF($A$2:$A$25,2023,C$2:C$25) -> 268000 | C32: =SUMIF($A$2:$A$25,2023,D$2:D$25) -> 218800 | D32: =E32/C32 -> 229.49305 | E32: =SUMIF($A$2:$A$25,2023,F$2:F$25) -> 50213080 | F32: =SUMIF($A$2:$A$25,2023,G$2:G$25) -> 45760000 | G32: =E32-F32 -> 4453080 | H32: =C32/B32 -> 0.81641791 | I32: - | J32: =F32/C32 -> 209.14077 | K32: =F32/E32 -> 0.91131633 | L32: =((E32-E31)/E31) -> 0.11201609
A33: 2024 | B33: =SUMIF($A$2:$A$25,2024,C$2:C$25) -> 284000 | C33: =SUMIF($A$2:$A$25,2024,D$2:D$25) -> 235320 | D33: =E33/C33 -> 235.90656 | E33: =SUMIF($A$2:$A$25,2024,F$2:F$25) -> 55513531 | F33: =SUMIF($A$2:$A$25,2024,G$2:G$25) -> 50080000 | G33: =E33-F33 -> 5433531 | H33: =C33/B33 -> 0.82859155 | I33: - | J33: =F33/C33 -> 212.81659 | K33: =F33/E33 -> 0.9021224 | L33: =((E33-E32)/E32) -> 0.10555917

Sheet ASSUMPTIONS
A1: DELOITTE — ENGAGEMENT MODEL ASSUMPTIONS | C1: Derivation
A3: HISTORICAL AVERAGES
A4: Avg Audit Utilization % (2019-2024) | B4: =AVERAGE(ACTUALS!I2:I7) -> 0.77643337 | C4: Average of the Utilization percentage
A5: Avg Tax Utilization % (2019-2024) | B5: =AVERAGE(ACTUALS!I8:I13) -> 0.805
A6: Avg Consulting Utilization % (2019-2024) | B6: =AVERAGE(ACTUALS!I14:I19) -> 0.79166667
A7: Avg Advisory Utilization % (2019-2024) | B7: =AVERAGE(ACTUALS!I20:I25) -> 0.78666667
A8: Avg Audit Realization % (2019-2024) | B8: =AVERAGE(ACTUALS!J2:J7) -> 0.90035632 | C8: Average of the realization percentage
A9: Avg Tax Realization % (2019-2024) | B9: =AVERAGE(ACTUALS!J8:J13) -> 0.9005288
A10: Avg Consulting Realization % (2019-2024) | B10: =AVERAGE(ACTUALS!J14:J19) -> 0.90143912
A11: Avg Advisory Realization % (2019-2024) | B11: =AVERAGE(ACTUALS!J20:J25) -> 0.89970872
A12: Avg Audit Revenue Growth % (YoY) | B12: =AVERAGE(ACTUALS!M3:M7) -> 0.079822153 | C12: Average of the revenue growth percentage
A13: Avg Tax Revenue Growth % (YoY) | B13: =AVERAGE(ACTUALS!M9:M13) -> 0.069562055
A14: Avg Consulting Revenue Growth % (YoY) | B14: =AVERAGE(ACTUALS!M15:M19) -> 0.1045579
A15: Avg Advisory Revenue Growth % (YoY) | B15: =AVERAGE(ACTUALS!M21:M25) -> 0.10079154
A17: RATE ASSUMPTIONS | B17: BEAR | C17: BASE | D17: BULL
A18: Audit Standard Rate 2025 | B18: =C18-3 -> 222.21228 | C18: 225.21228 | D18: =C18+3 -> 228.21228 | F18: Weighted average of the 2023 and 2024 rate of the respective service lines
A19: Tax Standard Rate 2025 | B19: =C19-3 -> 254.97043 | C19: 257.97043 | D19: =C19+3 -> 260.97043
A20: Consulting Standard Rate 2025 | B20: =C20-3 -> 322.53411 | C20: 325.53411 | D20: =C20+3 -> 328.53411
A21: Advisory Standard Rate 2025 | B21: =C21-3 -> 295.91811 | C21: 298.91811 | D21: =C21+3 -> 301.91811
A22: Annual Rate Increase % | B22: 0.023692172 | F22: Derived from the weighted averages of the average growth of tax,audit,advisory and consulting
A24: COST ASSUMPTIONS | B24: BEAR | C24: BASE | D24: BULL
A25: Avg Cost per Hour — Audit | B25: =C25-3 -> 181.09756 | C25: 184.09756 | D25: =C25+3 -> 187.09756 | G25: Average cost of the cost of delivery divided by the billed hours
A26: Avg Cost per Hour — Tax | B26: =C26-3 -> 207.07815 | C26: 210.07815 | D26: =C26+3 -> 213.07815
A27: Avg Cost per Hour — Consulting | B27: =C27-3 -> 257.05952 | C27: 260.05952 | D27: =C27+3 -> 263.05952
A28: Avg Cost per Hour — Advisory | B28: =C28-3 -> 237.3759 | C28: 240.3759 | D28: =C28+3 -> 243.3759
A29: Annual Rate Increase % | B29: 0.02 | G29: Average growth rate of the average growth rates of the service-lines
A31: FORECAST ASSUMPTIONS | B31: BEAR | C31: BASE | D31: BULL | I31: Hours Growth | J31: 2025 | K31: 2026
A32: Target Utilization % 2025 | B32: 0.82489484 | C32: 0.82493946 | D32: 0.81758931 | E32: Base gotten from the weighted average of 2023 and 2024 Utilization, and the bull and bear is derived from the adding of the base to the average of the growth rates between the utilization rates | I32: Audit | J32: =(ACTUALS!C7*(1+ASSUMPTIONS!B44)) -> 104694.25 | K32: =(J32*(1+$B$44)) -> 109608.86
A33: Target Utilization % 2026 | B33: 0.81118371 | C33: 0.82214531 | D33: 0.83310692 | E33: Base gotten from the weighted average of 2024 and 2025 Utilization, and the bull and bear is derived from the adding of the base to the average of the growth rates between the utilization rates | I33: Tax | J33: =(ACTUALS!C13*(1+ASSUMPTIONS!B44)) -> 77473.744 | K33: =(J33*(1+$B$44)) -> 81110.554
A34: Target Realization % | B34: 0.88 | C34: 0.9 | D34: 0.92 | I34: Consulting | J34: =(ACTUALS!C19*(1+ASSUMPTIONS!B44)) -> 62816.549 | K34: =(J34*(1+$B$44)) -> 65765.314
A35: Headcount Growth % | B35: 0.03 | C35: 0.04 | D35: 0.05 | I35: Advisory | J35: =(ACTUALS!C25*(1+ASSUMPTIONS!B44)) -> 52347.124 | K35: =(J35*(1+$B$44)) -> 54804.429
A36: Available Hours Growth % | B36: 0.0446334 | C36: 0.046942487 | D36: 0.049251574 | E36: The base is derived by the weighted average of the year 2024 and 2023 , the bear and base is gotten from the weighted average of the the change rate between(2024-2023) and (2023-2022) , I started from that time period because it appeared more stable ) | I36: Billable Hours | J36: 2025 | K36: 2026
I37: Audit | J37: =J32*$B$40 -> 86366.417 | K37: =K32*$B$41 -> 90114.408
A38: SCENARIO TOGGLE | I38: Tax | J38: =J33*$B$40 -> 63911.148 | K38: =K33*$B$41 -> 66684.662
A39: Active Scenario | B39: Base | I39: Consulting | J39: =J34*$B$40 -> 51819.85 | K39: =K34*$B$41 -> 54068.645
A40: Target Utilization % 2025 | B40: =IF($B$39="Base",C32,IF($B$39="Bear",B32,D32)) -> 0.82493946 | I40: Advisory | J40: =J35*$B$40 -> 43183.208 | K40: =K35*$B$41 -> 45057.204
A41: Target Utilization % 2026 | B41: =IF($B$39="Base",C33,IF($B$39="Bear",B33,D33)) -> 0.82214531
A42: Target Realization % | B42: =IF($B$39="Base",C34,IF($B$39="Bear",B34,D34)) -> 0.9
A43: Headcount Growth % | B43: =IF($B$39="Base",C35,IF($B$39="Bear",B35,D35)) -> 0.04
A44: Available Hours Growth % | B44: =IF($B$39="Base",C36,IF($B$39="Bear",B36,D36)) -> 0.046942487
...

Sheet REVENUE
A1: DELOITTE — REVENUE FORECAST
A3: Service line | B3: 2019 A | C3: 2020 A | D3: 2021 A | E3: 2022 A | F3: 2023 A | G3: 2024 A | H3: 2025 F | I3: 2026 F
A4: Audit | B4: =SUMIFS(ACTUALS!$F$2:$F$25,ACTUALS!$A$2:$A$25,2019,ACTUALS!$B$2:$B$25,"Audit") -> 11219625 | C4: =SUMIFS(ACTUALS!$F$2:$F$25,ACTUALS!$A$2:$A$25,2020,ACTUALS!$B$2:$B$25,"Audit") -> 10498302 | D4: =SUMIFS(ACTUALS!$F$2:$F$25,ACTUALS!$A$2:$A$25,2021,ACTUALS!$B$2:$B$25,"Audit") -> 12322387 | E4: =SUMIFS(ACTUALS!$F$2:$F$25,ACTUALS!$A$2:$A$25,2022,ACTUALS!$B$2:$B$25,"Audit") -> 13596595 | F4: =SUMIFS(ACTUALS!$F$2:$F$25,ACTUALS!$A$2:$A$25,2023,ACTUALS!$B$2:$B$25,"Audit") -> 15043680 | G4: =SUMIFS(ACTUALS!$F$2:$F$25,ACTUALS!$A$2:$A$25,2024,ACTUALS!$B$2:$B$25,"Audit") -> 16244400 | H4: =(ASSUMPTIONS!J37*ASSUMPTIONS!B49)*ASSUMPTIONS!$B$42 -> 17505700 | I4: =(ASSUMPTIONS!K37*(ASSUMPTIONS!B49*(1+ASSUMPTIONS!$B$22))*ASSUMPTIONS!$B$42) -> 18698131
A5: Tax | B5: =SUMIFS(ACTUALS!$F$2:$F$25,ACTUALS!$A$2:$A$25,2019,ACTUALS!$B$2:$B$25,"Tax") -> 10066800 | C5: =SUMIFS(ACTUALS!$F$2:$F$25,ACTUALS!$A$2:$A$25,2020,ACTUALS!$B$2:$B$25,"Tax") -> 9471744 | D5: =SUMIFS(ACTUALS!$F$2:$F$25,ACTUALS!$A$2:$A$25,2021,ACTUALS!$B$2:$B$25,"Tax") -> 10692864 | E5: =SUMIFS(ACTUALS!$F$2:$F$25,ACTUALS!$A$2:$A$25,2022,ACTUALS!$B$2:$B$25,"Tax") -> 11630527 | F5: =SUMIFS(ACTUALS!$F$2:$F$25,ACTUALS!$A$2:$A$25,2023,ACTUALS!$B$2:$B$25,"Tax") -> 12657870 | G5: =SUMIFS(ACTUALS!$F$2:$F$25,ACTUALS!$A$2:$A$25,2024,ACTUALS!$B$2:$B$25,"Tax") -> 13948675 | H5: =(ASSUMPTIONS!J38*ASSUMPTIONS!B50)*ASSUMPTIONS!$B$42 -> 14838468 | I5: =(ASSUMPTIONS!K38*(ASSUMPTIONS!B50*(1+ASSUMPTIONS!$B$22))*ASSUMPTIONS!$B$42) -> 15849215
A6: Consulting | B6: =SUMIFS(ACTUALS!$F$2:$F$25,ACTUALS!$A$2:$A$25,2019,ACTUALS!$B$2:$B$25,"Consulting") -> 8926898 | C6: =SUMIFS(ACTUALS!$F$2:$F$25,ACTUALS!$A$2:$A$25,2020,ACTUALS!$B$2:$B$25,"Consulting") -> 8313228 | D6: =SUMIFS(ACTUALS!$F$2:$F$25,ACTUALS!$A$2:$A$25,2021,ACTUALS!$B$2:$B$25,"Consulting") -> 9954144 | E6: =SUMIFS(ACTUALS!$F$2:$F$25,ACTUALS!$A$2:$A$25,2022,ACTUALS!$B$2:$B$25,"Consulting") -> 11335168 | F6: =SUMIFS(ACTUALS!$F$2:$F$25,ACTUALS!$A$2:$A$25,2023,ACTUALS!$B$2:$B$25,"Consulting") -> 12824038 | G6: =SUMIFS(ACTUALS!$F$2:$F$25,ACTUALS!$A$2:$A$25,2024,ACTUALS!$B$2:$B$25,"Consulting") -> 14414976 | H6: =(ASSUMPTIONS!J39*ASSUMPTIONS!B51)*ASSUMPTIONS!$B$42 -> 15182216 | I6: =(ASSUMPTIONS!K39*(ASSUMPTIONS!B51*(1+ASSUMPTIONS!$B$22))*ASSUMPTIONS!$B$42) -> 16216379
A7: Advisory | B7: =SUMIFS(ACTUALS!$F$2:$F$25,ACTUALS!$A$2:$A$25,2019,ACTUALS!$B$2:$B$25,"Advisory") -> 6886208 | C7: =SUMIFS(ACTUALS!$F$2:$F$25,ACTUALS!$A$2:$A$25,2020,ACTUALS!$B$2:$B$25,"Advisory") -> 6330758 | D7: =SUMIFS(ACTUALS!$F$2:$F$25,ACTUALS!$A$2:$A$25,2021,ACTUALS!$B$2:$B$25,"Advisory") -> 7637760 | E7: =SUMIFS(ACTUALS!$F$2:$F$25,ACTUALS!$A$2:$A$25,2022,ACTUALS!$B$2:$B$25,"Advisory") -> 8592704 | F7: =SUMIFS(ACTUALS!$F$2:$F$25,ACTUALS!$A$2:$A$25,2023,ACTUALS!$B$2:$B$25,"Advisory") -> 9687492 | G7: =SUMIFS(ACTUALS!$F$2:$F$25,ACTUALS!$A$2:$A$25,2024,ACTUALS!$B$2:$B$25,"Advisory") -> 10905480 | H7: =(ASSUMPTIONS!J40*ASSUMPTIONS!B52)*ASSUMPTIONS!$B$42 -> 11617419 | I7: =(ASSUMPTIONS!K40*(ASSUMPTIONS!B52*(1+ASSUMPTIONS!$B$22))*ASSUMPTIONS!$B$42) -> 12408759
A8: Total | B8: =SUM(B4:B7) -> 37099531 | C8: =SUM(C4:C7) -> 34614032 | D8: =SUM(D4:D7) -> 40607155 | E8: =SUM(E4:E7) -> 45154994 | F8: =SUM(F4:F7) -> 50213080 | G8: =SUM(G4:G7) -> 55513531 | H8: =SUM(H4:H7) -> 59143802 | I8: =SUM(I4:I7) -> 63172484

Sheet P&L
A1: ACTIVE SCENARIO | B1: =ASSUMPTIONS!B39 -> Base
B2: 2019 A | C2: 2020 A | D2: 2021 A | E2: 2022 A | F2: 2023 A | G2: 2024 A | H2: 2025 F | I2: 2026 F
A3: REVENUE
A4: Net Revenue — Audit | B4: =REVENUE!B4 -> 11219625 | C4: =REVENUE!C4 -> 10498302 | D4: =REVENUE!D4 -> 12322387 | E4: =REVENUE!E4 -> 13596595 | F4: =REVENUE!F4 -> 15043680 | G4: =REVENUE!G4 -> 16244400 | H4: =REVENUE!H4 -> 17505700 | I4: =REVENUE!I4 -> 18698131
A5: Net Revenue — Tax | B5: =REVENUE!B5 -> 10066800 | C5: =REVENUE!C5 -> 9471744 | D5: =REVENUE!D5 -> 10692864 | E5: =REVENUE!E5 -> 11630527 | F5: =REVENUE!F5 -> 12657870 | G5: =REVENUE!G5 -> 13948675 | H5: =REVENUE!H5 -> 14838468 | I5: =REVENUE!I5 -> 15849215
A6: Net Revenue — Consulting | B6: =REVENUE!B6 -> 8926898 | C6: =REVENUE!C6 -> 8313228 | D6: =REVENUE!D6 -> 9954144 | E6: =REVENUE!E6 -> 11335168 | F6: =REVENUE!F6 -> 12824038 | G6: =REVENUE!G6 -> 14414976 | H6: =REVENUE!H6 -> 15182216 | I6: =REVENUE!I6 -> 16216379
A7: Net Revenue — Advisory | B7: =REVENUE!B7 -> 6886208 | C7: =REVENUE!C7 -> 6330758 | D7: =REVENUE!D7 -> 7637760 | E7: =REVENUE!E7 -> 8592704 | F7: =REVENUE!F7 -> 9687492 | G7: =REVENUE!G7 -> 10905480 | H7: =REVENUE!H7 -> 11617419 | I7: =REVENUE!I7 -> 12408759
A8: Total Net Revenue | B8: =REVENUE!B8 -> 37099531 | C8: =REVENUE!C8 -> 34614032 | D8: =REVENUE!D8 -> 40607155 | E8: =REVENUE!E8 -> 45154994 | F8: =REVENUE!F8 -> 50213080 | G8: =REVENUE!G8 -> 55513531 | H8: =REVENUE!H8 -> 59143802 | I8: =REVENUE!I8 -> 63172484
A10: COST OF DELIVERY
A11: Direct Labour — Audit | B11: =ACTUALS!D2*ACTUALS!K2 -> 10455000 | C11: =ACTUALS!D3*ACTUALS!K3 -> 9880000 | D11: =ACTUALS!D4*ACTUALS!$K$4 -> 11450000 | E11: =ACTUALS!D5*ACTUALS!$K$5 -> 12480000 | F11: =ACTUALS!D6*ACTUALS!$K$6 -> 13750000 | G11: =ACTUALS!D7*ACTUALS!$K$7 -> 14800000 | H11: =ASSUMPTIONS!B45*ASSUMPTIONS!J37 -> 15899847 | I11: =((ASSUMPTIONS!B45*(1+ASSUMPTIONS!$B$29))*ASSUMPTIONS!K37) -> 16921640
A12: Direct Labour — Tax | B12: =ACTUALS!D8*ACTUALS!K8 -> 9275000 | C12: =ACTUALS!D9*ACTUALS!K9 -> 8920000 | D12: =ACTUALS!D10*ACTUALS!$K$10 -> 9850000 | E12: =ACTUALS!D11*ACTUALS!$K$11 -> 10620000 | F12: =ACTUALS!D12*ACTUALS!$K$12 -> 11580000 | G12: =ACTUALS!D13*ACTUALS!$K$13 -> 12650000 | H12: =ASSUMPTIONS!B46*ASSUMPTIONS!J38 -> 13426336 | I12: =((ASSUMPTIONS!B46*(1+ASSUMPTIONS!$B$29))*ASSUMPTIONS!K38) -> 14289170
A13: Direct Labour — Consulting | B13: =ACTUALS!D14*ACTUALS!K14 -> 8250000 | C13: =ACTUALS!D15*ACTUALS!K15 -> 7780000 | D13: =ACTUALS!D16*ACTUALS!$K$16 -> 9120000 | E13: =ACTUALS!D17*ACTUALS!$K$17 -> 10280000 | F13: =ACTUALS!D18*ACTUALS!$K$18 -> 11580000 | G13: =ACTUALS!D19*ACTUALS!$K$19 -> 12850000 | H13: =ASSUMPTIONS!B47*ASSUMPTIONS!J39 -> 13476246 | I13: =((ASSUMPTIONS!B47*(1+ASSUMPTIONS!$B$29))*ASSUMPTIONS!K39) -> 14342287
A14: Direct Labour — Advisory | B14: =ACTUALS!D20*ACTUALS!K20 -> 6420000 | C14: =ACTUALS!D21*ACTUALS!K21 -> 5980000 | D14: =ACTUALS!D22*ACTUALS!$K$22 -> 7080000 | E14: =ACTUALS!D23*ACTUALS!$K$23 -> 7920000 | F14: =ACTUALS!D24*ACTUALS!$K$24 -> 8850000 | G14: =ACTUALS!D25*ACTUALS!$K$25 -> 9780000 | H14: =ASSUMPTIONS!B48*ASSUMPTIONS!J40 -> 10380203 | I14: =((ASSUMPTIONS!B48*(1+ASSUMPTIONS!$B$29))*ASSUMPTIONS!K40) -> 11047279
A15: Total Direct Labour | B15: =SUM(B11:B14) -> 34400000 | C15: =SUM(C11:C14) -> 32560000 | D15: =SUM(D11:D14) -> 37500000 | E15: =SUM(E11:E14) -> 41300000 | F15: =SUM(F11:F14) -> 45760000 | G15: =SUM(G11:G14) -> 50080000 | H15: =SUM(H11:H14) -> 53182631 | I15: =SUM(I11:I14) -> 56600377
A17: Overhead Allocation
A18: Total Cost of Delivery | B18: =B15 -> 34400000 | C18: =C15 -> 32560000 | D18: =D15 -> 37500000 | E18: =E15 -> 41300000 | F18: =F15 -> 45760000 | G18: =G15 -> 50080000 | H18: =H15 -> 53182631 | I18: =I15 -> 56600377
A20: ENGAGEMENT MARGIN
A21: Gross Margin | B21: =B8-B18 -> 2699531 | C21: =C8-C18 -> 2054032 | D21: =D8-D18 -> 3107155 | E21: =E8-E18 -> 3854994 | F21: =F8-F18 -> 4453080 | G21: =G8-G18 -> 5433531 | H21: =H8-H18 -> 5961171.4 | I21: =I8-I18 -> 6572107.6
A22: Gross Margin % | B22: =B21/B8 -> 0.072764559 | C22: =C21/C8 -> 0.059341021 | D22: =D21/D8 -> 0.076517427 | E22: =E21/E8 -> 0.085372484 | F22: =F21/F8 -> 0.088683666 | G22: =G21/G8 -> 0.097877597 | H22: =H21/H8 -> 0.10079114 | I22: =I21/I8 -> 0.10403434
A24: Revenue Growth | B24: - | C24: =(C8-B8)/B8 -> -0.066995429 | D24: =(D8-C8)/C8 -> 0.17314143 | E24: =(E8-D8)/D8 -> 0.111996 | F24: =(F8-E8)/E8 -> 0.11201609 | G24: =(G8-F8)/F8 -> 0.10555917 | H24: =(H8-G8)/G8 -> 0.065394348 | I24: =(I8-H8)/H8 -> 0.068116724
A25: Gross Margin Growth | B25: - | C25: =((C21-B21)/B21) -> -0.23911524 | D25: =((D21-C21)/C21) -> 0.51271012 | E25: =((E21-D21)/D21) -> 0.24068288 | F25: =((F21-E21)/E21) -> 0.15514577 | G25: =((G21-F21)/F21) -> 0.22017368 | H25: =((H21-G21)/G21) -> 0.097108193 | I25: =((I21-H21)/H21) -> 0.10248593

Sheet SCENARIO
A1: DELOITTE SCENARIO 2025 & 2026
A3: Base | B3: 2025 | G3: Base | H3: 2026
A4: Service Line | B4: Audit | C4: Tax | D4: Consulting | E4: Advisory | G4: Service Line | H4: Audit | I4: Tax | J4: Consulting | K4: Advisory
A5: Net Revenue | B5: 17505700 | C5: 14838468 | D5: 15182216 | E5: 11617419 | G5: Net Revenue | H5: 18698131 | I5: 15849215 | J5: 16216379 | K5: 12408759
A6: Cost of delivery | B6: 15899847 | C6: 13426336 | D6: 13476246 | E6: 10380203 | G6: Cost of delivery | H6: 16921640 | I6: 14289170 | J6: 14342287 | K6: 11047279
A7: Percentage | B7: =B6/B5 -> 0.90826685 | C7: =C6/C5 -> 0.90483304 | D7: =D6/D5 -> 0.88763364 | E7: =E6/E5 -> 0.89350335 | G7: Percentage | H7: =H6/H5 -> 0.90499098 | I7: =I6/I5 -> 0.90156956 | J7: =J6/J5 -> 0.88443219 | K7: =K6/K5 -> 0.89028074
A8: Engagement Margin | B8: =B5-B6 -> 1605853 | C8: =C5-C6 -> 1412131.8 | D8: =D5-D6 -> 1705970.4 | E8: =E5-E6 -> 1237216.2 | G8: Engagement Margin | H8: =H5-H6 -> 1776491 | I8: =I5-I6 -> 1560045.2 | J8: =J5-J6 -> 1874091.4 | K8: =K5-K6 -> 1361480
A9: Margin % | B9: =B8/B5 -> 0.091733153 | C9: =C8/C5 -> 0.095166956 | D9: =D8/D5 -> 0.11236636 | E9: =E8/E5 -> 0.10649665 | G9: Margin % | H9: =H8/H5 -> 0.095009018 | I9: =I8/I5 -> 0.098430436 | J9: =J8/J5 -> 0.11556781 | K9: =K8/K5 -> 0.10971926
A12: Bear | B12: 2025 | G12: =A12 -> Bear | H12: 2026
A13: Service Line | B13: Audit | C13: Tax | D13: Consulting | E13: Advisory | G13: Service Line | H13: Audit | I13: Tax | J13: Consulting | K13: Advisory
A14: Net Revenue | B14: 16850516 | C14: 14307597 | D14: 14674796 | E14: 11219841 | G14: Net Revenue | H14: 17720140 | I14: 15045985 | J14: 15432134 | K14: 11798876
A15: Cost of delivery | B15: 15605407 | C15: 13204698 | D15: 13290687 | E15: 10227492 | G15: Cost of delivery | H15: 16351583 | I15: 13836084 | J15: 13926185 | K15: 10716522
A16: Percentage | B16: =B15/B14 -> 0.92610852 | C16: =C15/C14 -> 0.92291519 | D16: =D15/D14 -> 0.90568125 | E16: =E15/E14 -> 0.91155401 | G16: Percentage | H16: =H15/H14 -> 0.9227683 | I16: =I15/I14 -> 0.91958649 | J16: =J15/J14 -> 0.90241471 | K16: =K15/K14 -> 0.90826629
A17: Engagement Margin | B17: =B14-B15 -> 1245109.7 | C17: =C14-C15 -> 1102898.4 | D17: =D14-D15 -> 1384108.5 | E17: =E14-E15 -> 992349.93 | G17: Engagement Margin | H17: =H14-H15 -> 1368556.5 | I17: =I14-I15 -> 1209900.4 | J17: =J14-J15 -> 1505949.3 | K17: =K14-K15 -> 1082354.6
A18: Margin % | B18: =B17/B14 -> 0.073891484 | C18: =C17/C14 -> 0.077084811 | D18: =D17/D14 -> 0.094318754 | E18: =E17/E14 -> 0.088445986 | G18: Margin % | H18: 0.077231699 | I18: 0.080413509 | J18: 0.097585294 | K18: 0.091733707
A21: Bull | B21: 2025 | G21: =A21 -> Bull | H21: 2026
A22: Service Line | B22: Audit | C22: Tax | D22: Consulting | E22: Advisory | G22: Service Line | H22: Audit | I22: Tax | J22: Consulting | K22: Advisory
A23: Net Revenue | B23: 18011159 | C23: 15241429 | D23: 15557305 | E23: 11914116 | G23: Net Revenue | H23: 19713159 | I23: 16681697 | J23: 17027423 | K23: 13039964
A24: Cost of delivery | B24: 16050293 | C24: 13526501 | D24: 13540045 | E24: 10439085 | G24: Cost of delivery | H24: 17503637 | I24: 14751317 | J24: 14766088 | K24: 11384337
A25: Percentage | B25: =B24/B23 -> 0.89113047 | C25: =C24/C23 -> 0.88748249 | D25: =D24/D23 -> 0.87033357 | E25: =E24/E23 -> 0.87619461 | G25: Percentage | H25: =H24/H23 -> 0.88791641 | I25: =I24/I23 -> 0.88428159 | J25: =J24/J23 -> 0.86719452 | K25: =K24/K23 -> 0.87303442
A26: Engagement Margin | B26: =B23-B24 -> 1960866.5 | C26: =C23-C24 -> 1714927.6 | D26: =D23-D24 -> 2017260.3 | E26: =E23-E24 -> 1475031.8 | G26: Engagement Margin | H26: =H23-H24 -> 2209521.6 | I26: =I23-I24 -> 1930379.4 | J26: =J23-J24 -> 2261335.1 | K26: =K23-K24 -> 1655626.5
A27: Margin % | B27: =B26/B23 -> 0.10886953 | C27: =C26/C23 -> 0.11251751 | D27: =D26/D23 -> 0.12966643 | E27: =E26/E23 -> 0.12380539 | G27: Margin % | H27: =H26/H23 -> 0.11208359 | I27: =I26/I23 -> 0.11571841 | J27: =J26/J23 -> 0.13280548 | K27: =K26/K23 -> 0.12696558

Sheet DASHBOARD
A1: ACTIVE SCENARIO | B1: =ASSUMPTIONS!B39 -> Base
A2: Revenue Summary
A3: Metric | B3: 2019A | C3: 2020A | D3: 2021A | E3: 2022A | F3: 2023A | G3: 2024A | H3: 2025F | I3: 2026F
A4: YoY Growth % | B4: - | C4: ='P&L'!C24 -> -0.066995429 | D4: ='P&L'!D24 -> 0.17314143 | E4: ='P&L'!E24 -> 0.111996 | F4: ='P&L'!F24 -> 0.11201609 | G4: ='P&L'!G24 -> 0.10555917 | H4: ='P&L'!H24 -> 0.065394348 | I4: ='P&L'!I24 -> 0.068116724
A5: Total Cost of delivery | B5: ='P&L'!B15 -> 34400000 | C5: ='P&L'!C15 -> 32560000 | D5: ='P&L'!D15 -> 37500000 | E5: ='P&L'!E15 -> 41300000 | F5: ='P&L'!F15 -> 45760000 | G5: ='P&L'!G15 -> 50080000 | H5: ='P&L'!H15 -> 53182631 | I5: ='P&L'!I15 -> 56600377
A6: Gross Margin | B6: ='P&L'!B21 -> 2699531 | C6: ='P&L'!C21 -> 2054032 | D6: ='P&L'!D21 -> 3107155 | E6: ='P&L'!E21 -> 3854994 | F6: ='P&L'!F21 -> 4453080 | G6: ='P&L'!G21 -> 5433531 | H6: ='P&L'!H21 -> 5961171.4 | I6: ='P&L'!I21 -> 6572107.6
A7: GrossMargin % | B7: ='P&L'!B22 -> 0.072764559 | C7: ='P&L'!C22 -> 0.059341021 | D7: ='P&L'!D22 -> 0.076517427 | E7: ='P&L'!E22 -> 0.085372484 | F7: ='P&L'!F22 -> 0.088683666 | G7: ='P&L'!G22 -> 0.097877597 | H7: ='P&L'!H22 -> 0.10079114 | I7: ='P&L'!I22 -> 0.10403434
A9: Service Line Breakdown
A10: Service line | B10: 2024A Revenue | C10: 2025F Revenue | D10: 2025 Growth | E10: 2026F Revenue | F10: 2026 Growth
A11: Audit | B11: =REVENUE!G4 -> 16244400 | C11: =REVENUE!H4 -> 17505700 | D11: =((C11-B11)/B11) -> 0.077645201 | E11: =REVENUE!I4 -> 18698131 | F11: =((E11-C11)/C11) -> 0.068116724
A12: Tax | B12: =REVENUE!G5 -> 13948675 | C12: =REVENUE!H5 -> 14838468 | D12: =((C12-B12)/B12) -> 0.063790477 | E12: =REVENUE!I5 -> 15849215 | F12: =((E12-C12)/C12) -> 0.068116724
A13: Consulting | B13: =REVENUE!G6 -> 14414976 | C13: =REVENUE!H6 -> 15182216 | D13: =((C13-B13)/B13) -> 0.053225196 | E13: =REVENUE!I6 -> 16216379 | F13: =((E13-C13)/C13) -> 0.068116724
A14: Advisory | B14: =REVENUE!G7 -> 10905480 | C14: =REVENUE!H7 -> 11617419 | D14: =((C14-B14)/B14) -> 0.065282674 | E14: =REVENUE!I7 -> 12408759 | F14: =((E14-C14)/C14) -> 0.068116724
A16: Key Metrcis
A17: Metrics | B17: 2024 Actual | C17: 2025F Base | D17: 2026F base
A18: Blended Utilization | B18: =(SUM(ACTUALS!D7,ACTUALS!D13,ACTUALS!D19,ACTUALS!D25))/(SUM(ACTUALS!C7,ACTUALS!C13,ACTUALS!C19,ACTUALS!C25)) -> 0.82859155 | C18: =(SUM(ASSUMPTIONS!J37:J40))/(SUM(ASSUMPTIONS!J32:J35)) -> 0.82493946 | D18: =(SUM(ASSUMPTIONS!K37:K40))/(SUM(ASSUMPTIONS!K32:K35)) -> 0.82214531
A19: Blended realization | B19: =((SUM(ACTUALS!F7,ACTUALS!F13,ACTUALS!F19,ACTUALS!F25))/((SUM((ACTUALS!E7*ACTUALS!D7),(ACTUALS!D13*ACTUALS!E13),(ACTUALS!D19*ACTUALS!E19),(ACTUALS!D25*ACTUALS!E25))))) -> 0.90027237 | C19: - | D19: -
A20: Revenue per billable Hour | B20: =ACTUALS!E33/ACTUALS!C33 -> 235.90656 | C20: =REVENUE!H8/(SUM(ASSUMPTIONS!J37:J40)) -> 241.12709 | D20: =REVENUE!I8/(SUM(ASSUMPTIONS!K37:K40)) -> 246.83991
A21: Margin per billable Hour | B21: =ACTUALS!G33/ACTUALS!C33 -> 23.089967 | C21: ='P&L'!H21/(SUM(ASSUMPTIONS!J37:J40)) -> 24.303474 | D21: ='P&L'!I21/(SUM(ASSUMPTIONS!K37:K40)) -> 25.679827
A23: Scenario Comparison
B24: Bear 2025 | C24: Base 2025 | D24: Bull 2025
A25: Total Revenue | B25: =SUM(SCENARIO!B14:E14) -> 57052751 | C25: =SUM(SCENARIO!B5:E5) -> 59143802 | D25: =SUM(SCENARIO!B23:E23) -> 60724010
A26: Total Cost | B26: =SUM(SCENARIO!B15:E15) -> 52328284 | C26: =SUM(SCENARIO!B6:E6) -> 53182631 | D26: =SUM(SCENARIO!B24:E24) -> 53555923
A27: Gross margin | B27: =B25-B26 -> 4724466.5 | C27: =C25-C26 -> 5961171.4 | D27: =D25-D26 -> 7168086.1
A28: Gross Margin % | B28: =B27/B25 -> 0.082808741 | C28: =C27/C25 -> 0.10079114 | D28: =D27/D25 -> 0.11804369

Sheet CHARTS

Sheet INSIGHT
A1: Executive Summary
B2: Deloitte Canada's engagement model demonstrates strong and consistent revenue growth from $37.1M in 2019 to $55.5M in 2024 — a 50% increase over six years. Despite a COVID-driven contraction in 2020, the practice recovered strongly in 2021 and has delivered double-digit growth in three of the last four years. Engagement margins have expanded from 7.3% in 2019 to 9.8% in 2024, driven by improving utilization rates and disciplined cost management. The 2025 and 2026 forecast projects continued growth to $59.1M and $63.2M respectively, with margins expanding to 10.1% and 10.4% under the Base scenario.
A14: REVENUE STORY -2019 TO 2026
B15: Revenue declined 6.7% in 2020 driven by COVID-19 disruption across all four service lines — Advisory was hardest hit at -8.1% as discretionary consulting spend was deferred. Recovery was swift and strong — 2021 delivered 17.3% growth as pent-up demand released and new mandates accelerated particularly in Consulting (+19.7%) and Advisory (+20.7%). From 2022 onwards revenue has grown consistently at 10-11% annually. Consulting and Advisory are the fastest-growing service lines at 10.5% and 10.1% average annual growth respectively, compared to Audit at 8.0% and Tax at 7.0%. The 2025-2026 forecast projects a slight moderation to 6.5-6.8% growth as the post-COVID recovery tailwind normalises and base effects become more challenging.
A27: MARGIN STORY — EXPANSION DRIVEN BY UTILIZATION
B28: Engagement margins have expanded 250 basis points from 7.3% in 2019 to 9.8% in 2024. The primary driver is utilization improvement — blended utilization across all service lines improved from 76.9% in 2019 to 82.9% in 2024, meaning more revenue is being generated from the same cost base. Realization rates have remained stable at approximately 90% throughout the period, indicating strong billing discipline and effective client relationship management. The 2020 margin compression to 5.9% was temporary — lower utilization as available hours were underdeployed during lockdowns — and fully recovered by 2021. Forecast margins of 10.1% in 2025 and 10.4% in 2026 assume continued utilization improvement to 82.5% and 82.2% respectively.
A40: SERVICE LINE HIGHLIGHTS
B41: Audit remains the largest service line at $16.2M (29% of revenue) but is growing slowest at 8.0% annually — reflecting maturity and increased competition from technology-driven audit tools. Tax at $13.9M (25%) shows steady 7.0% growth driven by increasing regulatory complexity. Consulting is the standout performer — growing from $8.9M in 2019 to $14.4M in 2024, a 61% increase — as demand for transformation and technology advisory services accelerated post-COVID. Advisory at $10.9M (20%) mirrors Consulting's trajectory with 60% cumulative growth. The forecast assumes Consulting and Advisory continue to outgrow Audit and Tax, reflecting structural demand shifts toward higher-value advisory services.
A53: SCENARIO ANALYSIS — KEY RISKS AND OPPORTUNITIES
B54: Bear Case (2025 Total Revenue: $57.1M, Margin: 8.3%) — assumes lower utilization at 82.0% and realization at 88%, reflecting potential headwinds from economic slowdown reducing client discretionary spend, increased competition for talent driving up cost per hour, and billing pressure from large clients seeking rate concessions. Under Bear, engagement margin per hour falls to $19.36 vs $24.30 in Base. Base Case (2025 Total Revenue: $59.1M, Margin: 10.1%) — assumes continuation of current utilization trends at 82.5% and 90% realization. Revenue growth moderates to 6.5% reflecting normalisation after strong post-COVID recovery. This is the most likely outcome given current pipeline visibility. Bull Case (2025 Total Revenue: $60.7M, Margin: 11.8%) — assumes utilization improves to 83.0% driven by large mandate wins and strong demand for Consulting and Advisory services. Realization improves to 92% reflecting stronger pricing power and reduced write-offs. Under Bull, engagement margin per hour reaches $29.41 — the highest in the model's history.
A77: KEY RECOMMENDATIONS
B78: 1.)Prioritize Consulting and Advisory investment — these service lines deliver the highest margins at 10-11% and are growing at 10%+ annually. Every incremental dollar invested here generates superior returns versus Audit. 2.)Defend 90% realization through billing discipline — realization has held steady throughout the model period. Any compression below 88% materially impacts margins as shown in the Bear case. 3.)Maintain utilization above 82% — the single biggest driver of the 250bps margin expansion over six years. Strong pipeline coverage and minimizing bench time is critical. 4.)Monitor cost per hour growth closely — the primary downside risk to the forecast. If talent competition drives cost per hour above 2% annually, margins compress back toward 8-9%. 5.)Invest in technology to protect Audit margins — Audit is the slowest growing service line at 8% annually and faces structural pressure from automated audit tools. Technology investment can protect margins while managing headcount growth. 6.)Build 6-month pipeline visibility — the key operational metric supporting the utilization assumption. Surprise gaps in pipeline are the fastest path to utilization falling below target.
