Workbook

Sheet Historical & Assumptions
A1: Revenue
A2: Metric | B2: 2020 | C2: 2021 | D2: 2022
A3: Self-Serve Revenue | B3: 267.7 | C3: 301.1 | D3: 299.6
A4: Sales-Assisted Revenue | B4: 107.9 | C4: 142.7 | D4: 181.3
A5: Total Revenue | B5: 375.6 | C5: 443.8 | D5: 480.9
A7: P&L
A8: Metric | B8: 2020 | C8: 2021 | D8: 2022
A9: Cost of Revenue | B9: 83.9 | C9: 86.4 | D9: 86.3
A10: Gross Profit | B10: 291.7 | C10: 357.4 | D10: 394.7
A11: Gross Margin % | B11: 0.776 | C11: 0.805 | D11: 0.82
A12: R&D | B12: 113 | C12: 139.3 | D12: 138.1
A13: Sales & Marketing | B13: 172.4 | C13: 224 | D13: 223.8
A14: G&A | B14: 87.9 | C14: 106.7 | D14: 107.5
A15: Restructuring | B15: 0 | C15: 0 | D15: 6.6
A16: Total OpEx | B16: 373.3 | C16: 469.9 | D16: 476
A17: Operating Loss | B17: -81.6 | C17: -112.6 | D17: -81.3
A18: GAAP Net Loss | B18: -91.6 | C18: -112.9 | D18: -89.9
A20: Customer Metrics
A21: Metric | B21: 2020 | C21: 2021 | D21: 2022 | E21: 2023
A22: Total Paying Users | B22: =830*1000 -> 830000 | C22: =880*1000 -> 880000 | D22: =887*1000 -> 887000
A23: Sales-Assisted Users | B23: 8200 | C23: 11900 | D23: 14500 | E23: =D23*(1+$B$87) -> 16965
A24: Company ARPU (Annual) | B24: =(B5*1000000)/B22 -> 452.53012 | C24: =(C5*1000000)/C22 -> 504.31818 | D24: =(D5*1000000)/D22 -> 542.1646
A26: Derived Metrics
A27: Metric | B27: 2020 | C27: 2021 | D27: 2022 | E27: 2023
A28: Self-Serve Users | B28: =B22-B23 -> 821800 | C28: =C22-C23 -> 868100 | D28: =D22-D23 -> 872500
A29: Self-Serve ARPU | B29: =(B3*1000000)/B28 -> 325.74836 | C29: =(C3*1000000)/C28 -> 346.84944 | D29: =(D3*1000000)/D28 -> 343.38109 | E29: =D29*(1+B88) -> 336.51347
A30: Sales-Assisted ARPU | B30: =(B4*1000000)/B23 -> 13158.537 | C30: =(C4*1000000)/C23 -> 11991.597 | D30: =(D4*1000000)/D23 -> 12503.448 | E30: =D30*(1+B89) -> 12753.517
A32: Expense Ratios — % of Revenue
A33: Metric | B33: 2020 | C33: 2021 | D33: 2022
A34: Cost of Revenue % | B34: 0.223 | C34: 0.195 | D34: 0.179
A35: R&D % | B35: 0.301 | C35: 0.314 | D35: 0.287
A36: Sales & Marketing % | B36: 0.459 | C36: 0.505 | D36: 0.465
A37: G&A % | B37: 0.234 | C37: 0.24 | D37: 0.224
A39: Growth Rates — Historical
A40: Metric | B40: 2021 | C40: 2022
A41: Self-Serve Revenue Growth | B41: 0.125 | C41: -0.005
A42: Sales-Assisted Revenue Growth | B42: 0.323 | C42: 0.271
A43: Total Revenue Growth | B43: 0.182 | C43: 0.084
A44: Sales-Assisted User Growth | B44: 0.451 | C44: 0.218
A45: Self-Serve ARPU Growth | B45: 0.064 | C45: -0.009
...

Sheet Sales-Assisted Revenue
A1: Sales Assisted Revenue Model
A4: Metrics | B4: 2020A | C4: 2021A | D4: 2022A | E4: 2023E | F4: 2024F | G4: 2025F | H4: 2026F
A5: Sales-Assisted Revenue(M) | B5: ='Historical & Assumptions'!B4 -> 107.9 | C5: ='Historical & Assumptions'!C4 -> 142.7 | D5: ='Historical & Assumptions'!D4 -> 181.3 | E5: =(E13*E12)/1000000 -> 216.36342 | F5: =(F13*F12)/1000000 -> 258.20811 | G5: =(G13*G12)/1000000 -> 308.14555 | H5: =(H13*H12)/1000000 -> 367.7409
A6: YoY Growth % | B6: - | C6: =(C5-B5)/B5 -> 0.32252085 | D6: =(D5-C5)/C5 -> 0.27049755 | E6: =(E5-D5)/D5 -> 0.1934 | F6: =(F5-E5)/E5 -> 0.1934 | G6: =(G5-F5)/F5 -> 0.1934 | H6: =(H5-G5)/G5 -> 0.1934
A8: Driver Section
A9: Beginning Customers | B9: ='Historical & Assumptions'!B23 -> 8200 | C9: =B12 -> 8200 | D9: =C12 -> 11900 | E9: =D12 -> 14500 | F9: =E9*(1+'Historical & Assumptions'!$B$87) -> 16965 | G9: =F9*(1+'Historical & Assumptions'!$B$87) -> 19849.05 | H9: =G9*(1+'Historical & Assumptions'!$B$87) -> 23223.388
A10: New Customers | B10: - | C10: ='Historical & Assumptions'!C23-('Historical & Assumptions'!B23-('Historical & Assumptions'!B23*'Historical & Assumptions'!$B$90)) -> 4930 | D10: ='Historical & Assumptions'!D23-('Historical & Assumptions'!C23-('Historical & Assumptions'!C23*'Historical & Assumptions'!$B$90)) -> 4385 | E10: =(E9*(1+'Historical & Assumptions'!$B$87))-(E9-(E9*'Historical & Assumptions'!$B$90)) -> 4640 | F10: =(F9*(1+'Historical & Assumptions'!$B$87))-(F9-(F9*'Historical & Assumptions'!$B$90)) -> 5428.8 | G10: =(G9*(1+'Historical & Assumptions'!$B$87))-(G9-(G9*'Historical & Assumptions'!$B$90)) -> 6351.696 | H10: =(H9*(1+'Historical & Assumptions'!$B$87))-(H9-(H9*'Historical & Assumptions'!$B$90)) -> 7431.4843
A11: Churned Customers | B11: - | C11: =C9*'Historical & Assumptions'!$B$90 -> 1230 | D11: =D9*'Historical & Assumptions'!$B$90 -> 1785 | E11: =E9*'Historical & Assumptions'!$B$90 -> 2175 | F11: =F9*'Historical & Assumptions'!$B$90 -> 2544.75 | G11: =G9*'Historical & Assumptions'!$B$90 -> 2977.3575 | H11: =H9*'Historical & Assumptions'!$B$90 -> 3483.5083
A12: Ending Customers | B12: =B9 -> 8200 | C12: =SUM(C9:C10)-C11 -> 11900 | D12: =SUM(D9:D10)-D11 -> 14500 | E12: =SUM(E9:E10)-E11 -> 16965 | F12: =SUM(F9:F10)-F11 -> 19849.05 | G12: =SUM(G9:G10)-G11 -> 23223.388 | H12: =SUM(H9:H10)-H11 -> 27171.365
A13: Sales-Assisted ARPU($) | B13: ='Historical & Assumptions'!B30 -> 13158.537 | C13: ='Historical & Assumptions'!C30 -> 11991.597 | D13: ='Historical & Assumptions'!D30 -> 12503.448 | E13: =D13*(1+'Historical & Assumptions'!$B$89) -> 12753.517 | F13: =E13*(1+'Historical & Assumptions'!$B$89) -> 13008.588 | G13: =F13*(1+'Historical & Assumptions'!$B$89) -> 13268.759 | H13: =G13*(1+'Historical & Assumptions'!$B$89) -> 13534.135
A14: ARPU Growth % | B14: - | C14: =(C13-B13)/B13 -> -0.08868311 | D14: =(D13-C13)/C13 -> 0.042684194 | E14: =(E13-D13)/D13 -> 0.02 | F14: =(F13-E13)/E13 -> 0.02 | G14: =(G13-F13)/F13 -> 0.02 | H14: =(H13-G13)/G13 -> 0.02
A16: Cross Check Section
A17: Variance Vs Revenue Line | B17: =((B13*B12)/1000000)-B5 -> 0 | C17: =((C13*C12)/1000000)-C5 -> 0 | D17: =((D13*D12)/1000000)-D5 -> 0 | E17: =((E13*E12)/1000000)-E5 -> 0 | F17: =((F13*F12)/1000000)-F5 -> 0 | G17: =((G13*G12)/1000000)-G5 -> 0 | H17: =((H13*H12)/1000000)-H5 -> 0
A19: Summary box
A20: N-Line | B20: =(H5-B5)/B5 -> 2.4081641

Sheet Self-Serve Revenue
A1: Self-Serve Revenue Model
A3: Metrics | B3: 2020A | C3: 2021A | D3: 2022A | E3: 2023E | F3: 2024F | G3: 2025F | H3: 2026F
A4: Self-Serve Revenue(M) | B4: ='Historical & Assumptions'!B3 -> 267.7 | C4: ='Historical & Assumptions'!C3 -> 301.1 | D4: ='Historical & Assumptions'!D3 -> 299.6 | E4: =(E12*E11)/1000000 -> 275.99152 | F4: =(F12*F11)/1000000 -> 254.24339 | G4: =(G12*G11)/1000000 -> 234.20901 | H4: =(H12*H11)/1000000 -> 215.75334
A5: YoY Growth % | B5: - | C5: =(C4-B4)/B4 -> 0.12476653 | D5: =(D4-C4)/C4 -> -0.0049817336 | E5: =(E4-D4)/D4 -> -0.0788 | F5: =(F4-E4)/E4 -> -0.0788 | G5: =(G4-F4)/F4 -> -0.0788 | H5: =(H4-G4)/G4 -> -0.0788
A7: Driver Section
A8: Beginning Customers | B8: ='Historical & Assumptions'!B28 -> 821800 | C8: =B11 -> 821800 | D8: =C11 -> 868100 | E8: =D11 -> 872500 | F8: =E11 -> 820150 | G8: =F11 -> 770941 | H8: =G11 -> 724684.54
A9: New Customers | B9: - | C9: =((C8*(1+'Historical & Assumptions'!$B$51))-(('Self-Serve Revenue'!C8-('Self-Serve Revenue'!C8*'Historical & Assumptions'!$B$90)))) -> 169570 | D9: =((D8*(1+'Historical & Assumptions'!$C$51))-(('Self-Serve Revenue'!D8-('Self-Serve Revenue'!D8*'Historical & Assumptions'!$B$90)))) -> 134615 | E9: =((E8*(1+'Historical & Assumptions'!$B$91))-(('Self-Serve Revenue'!E8-('Self-Serve Revenue'!E8*'Historical & Assumptions'!$B$90)))) -> 78525 | F9: =((F8*(1+'Historical & Assumptions'!$B$91))-(('Self-Serve Revenue'!F8-('Self-Serve Revenue'!F8*'Historical & Assumptions'!$B$90)))) -> 73813.5 | G9: =((G8*(1+'Historical & Assumptions'!$B$91))-(('Self-Serve Revenue'!G8-('Self-Serve Revenue'!G8*'Historical & Assumptions'!$B$90)))) -> 69384.69 | H9: =((H8*(1+'Historical & Assumptions'!$B$91))-(('Self-Serve Revenue'!H8-('Self-Serve Revenue'!H8*'Historical & Assumptions'!$B$90)))) -> 65221.609
A10: Churned Customers | C10: =B11*'Historical & Assumptions'!$B$90 -> 123270 | D10: =C11*'Historical & Assumptions'!$B$90 -> 130215 | E10: =D11*'Historical & Assumptions'!$B$90 -> 130875 | F10: =E11*'Historical & Assumptions'!$B$90 -> 123022.5 | G10: =F11*'Historical & Assumptions'!$B$90 -> 115641.15 | H10: =G11*'Historical & Assumptions'!$B$90 -> 108702.68
A11: Ending Customers | B11: =SUM(B8:B9) -> 821800 | C11: =SUM(C8:C9)-C10 -> 868100 | D11: =SUM(D8:D9)-D10 -> 872500 | E11: =SUM(E8:E9)-E10 -> 820150 | F11: =SUM(F8:F9)-F10 -> 770941 | G11: =SUM(G8:G9)-G10 -> 724684.54 | H11: =SUM(H8:H9)-H10 -> 681203.47
A12: Self-Serve ARPU($) | B12: ='Historical & Assumptions'!B29 -> 325.74836 | C12: ='Historical & Assumptions'!C29 -> 346.84944 | D12: ='Historical & Assumptions'!D29 -> 343.38109 | E12: =D12*(1+'Historical & Assumptions'!$B$88) -> 336.51347 | F12: =E12*(1+'Historical & Assumptions'!$B$88) -> 329.7832 | G12: =F12*(1+'Historical & Assumptions'!$B$88) -> 323.18753 | H12: =G12*(1+'Historical & Assumptions'!$B$88) -> 316.72378
A13: ARPU Growth % | B13: - | C13: =(C12-B12)/B12 -> 0.064777254 | D13: =(D12-C12)/C12 -> -0.0099995908 | E13: =(E12-D12)/D12 -> -0.02 | F13: =(F12-E12)/E12 -> -0.02 | G13: =(G12-F12)/F12 -> -0.02 | H13: =(H12-G12)/G12 -> -0.02
A15: Cross Check Section
A16: Variance Vs Revenue Line | B16: =(B4*1000000)-((B11*B12)) -> 0 | C16: =(C4*1000000)-((C11*C12)) -> 0 | D16: =(D4*1000000)-((D11*D12)) -> 0 | E16: =(E4*1000000)-((E11*E12)) -> 0 | F16: =(F4*1000000)-((F11*F12)) -> 0 | G16: =(G4*1000000)-((G11*G12)) -> 0 | H16: =(H4*1000000)-((H11*H12)) -> 0
A18: Summary box
A19: N-Line | B19: =(H4-B4)/B4 -> -0.19404804

Sheet Combined P&L
A1: SurveyMonkey — Combined P&L
A3: ='Historical & Assumptions'!B86 -> Downside
A4: P&L ($M) | B4: 2020A | C4: 2021A | D4: 2022A | E4: 2023E | F4: 2024F | G4: 2025F | H4: 2026F
A5: REVENUE
A6: Self-Serve Revenue | B6: ='Self-Serve Revenue'!B4 -> 267.7 | C6: ='Self-Serve Revenue'!C4 -> 301.1 | D6: ='Self-Serve Revenue'!D4 -> 299.6 | E6: ='Self-Serve Revenue'!E4 -> 275.99152 | F6: ='Self-Serve Revenue'!F4 -> 254.24339 | G6: ='Self-Serve Revenue'!G4 -> 234.20901 | H6: ='Self-Serve Revenue'!H4 -> 215.75334
A7: Sales-Assisted Revenue | B7: ='Sales-Assisted Revenue'!B5 -> 107.9 | C7: ='Sales-Assisted Revenue'!C5 -> 142.7 | D7: ='Sales-Assisted Revenue'!D5 -> 181.3 | E7: ='Sales-Assisted Revenue'!E5 -> 216.36342 | F7: ='Sales-Assisted Revenue'!F5 -> 258.20811 | G7: ='Sales-Assisted Revenue'!G5 -> 308.14555 | H7: ='Sales-Assisted Revenue'!H5 -> 367.7409
A8: Total Revenue | B8: =SUM(B6:B7) -> 375.6 | C8: =SUM(C6:C7) -> 443.8 | D8: =SUM(D6:D7) -> 480.9 | E8: =SUM(E6:E7) -> 492.35494 | F8: =SUM(F6:F7) -> 512.45149 | G8: =SUM(G6:G7) -> 542.35456 | H8: =SUM(H6:H7) -> 583.49424
A9: Revenue Growth % | B9: - | C9: =(C8-B8)/B8 -> 0.18157614 | D9: =(D8-C8)/C8 -> 0.083596215 | E9: =(E8-D8)/D8 -> 0.023819796 | F9: =(F8-E8)/E8 -> 0.040817207 | G9: =(G8-F8)/F8 -> 0.058352974 | H9: =(H8-G8)/G8 -> 0.075853847
A11: Cost of Revenue
A12: Gross Profit | B12: =B8-B13 -> 291.7 | C12: =C8-C13 -> 357.4 | D12: =D8-D13 -> 394.6 | E12: =E8*'Historical & Assumptions'!B94 -> 393.88395 | F12: =F8*'Historical & Assumptions'!C94 -> 407.39894 | G12: =G8*'Historical & Assumptions'!D94 -> 428.4601 | H12: =H8*'Historical & Assumptions'!E94 -> 458.04298
A13: Cost of Revenue | B13: ='Historical & Assumptions'!B9 -> 83.9 | C13: ='Historical & Assumptions'!C9 -> 86.4 | D13: ='Historical & Assumptions'!D9 -> 86.3 | E13: =E8-E12 -> 98.470988 | F13: =F8-F12 -> 105.05256 | G13: =G8-G12 -> 113.89446 | H13: =H8-H12 -> 125.45126
A14: Gross Margin % | B14: =(B12/B8) -> 0.77662407 | C14: =(C12/C8) -> 0.80531771 | D14: =(D12/D8) -> 0.82054481 | E14: =(E12/E8) -> 0.8 | F14: =(F12/F8) -> 0.795 | G14: =(G12/G8) -> 0.79 | H14: =(H12/H8) -> 0.785
A16: OPERATING EXPENSES
A17: Research & Development | B17: ='Historical & Assumptions'!B12 -> 113 | C17: ='Historical & Assumptions'!C12 -> 139.3 | D17: ='Historical & Assumptions'!D12 -> 138.1 | E17: =E8*'Historical & Assumptions'!B95 -> 147.70648 | F17: =F8*'Historical & Assumptions'!C95 -> 158.85996 | G17: =G8*'Historical & Assumptions'!D95 -> 173.55346 | H17: =H8*'Historical & Assumptions'!E95 -> 192.5531
A18: Sales & Marketing | B18: ='Historical & Assumptions'!B13 -> 172.4 | C18: ='Historical & Assumptions'!C13 -> 224 | D18: ='Historical & Assumptions'!D13 -> 223.8 | E18: =E8*'Historical & Assumptions'!B96 -> 236.33037 | F18: =F8*'Historical & Assumptions'!C96 -> 251.10123 | G18: =G8*'Historical & Assumptions'!D96 -> 271.17728 | H18: =H8*'Historical & Assumptions'!E96 -> 297.58206
A19: General & Administrative | B19: ='Historical & Assumptions'!B14 -> 87.9 | C19: ='Historical & Assumptions'!C14 -> 106.7 | D19: ='Historical & Assumptions'!D14 -> 107.5 | E19: =E8*'Historical & Assumptions'!B97 -> 113.24164 | F19: =F8*'Historical & Assumptions'!C97 -> 120.4261 | G19: =G8*'Historical & Assumptions'!D97 -> 130.16509 | H19: =H8*'Historical & Assumptions'!E97 -> 142.95609
A20: Restructuring | B20: ='Historical & Assumptions'!B15 -> 0 | C20: ='Historical & Assumptions'!C15 -> 0 | D20: ='Historical & Assumptions'!D15 -> 6.6 | E20: 0 | F20: 0 | G20: 0 | H20: 0
A21: Total Operating Expenses | B21: =SUM(B17:B20) -> 373.3 | C21: =SUM(C17:C20) -> 470 | D21: =SUM(D17:D20) -> 476 | E21: =SUM(E17:E20) -> 497.27849 | F21: =SUM(F17:F20) -> 530.3873 | G21: =SUM(G17:G20) -> 574.89584 | H21: =SUM(H17:H20) -> 633.09125
A23: Operating Income / (Loss) | B23: ='Historical & Assumptions'!B17 -> -81.6 | C23: ='Historical & Assumptions'!C17 -> -112.6 | D23: ='Historical & Assumptions'!D17 -> -81.3 | E23: =E12-E21 -> -103.39454 | F23: =F12-F21 -> -122.98836 | G23: =G12-G21 -> -146.43573 | H23: =H12-H21 -> -175.04827
A24: Operating Margin % | B24: =B23/B8 -> -0.2172524 | C24: =C23/C8 -> -0.25371789 | D24: =D23/D8 -> -0.16905802 | E24: =E23/E8 -> -0.21 | F24: =F23/F8 -> -0.24 | G24: =G23/G8 -> -0.27 | H24: =H23/H8 -> -0.3
A26: GAAP Net Income / (Loss) | B26: ='Historical & Assumptions'!B18 -> -91.6 | C26: ='Historical & Assumptions'!C18 -> -112.9 | D26: ='Historical & Assumptions'!D18 -> -89.9
A27: Net Margin % | B27: =B26/B8 -> -0.24387646 | C27: =C26/C8 -> -0.25439387 | D27: =D26/D8 -> -0.18694115

Sheet Scenarios
A1: SurveyMonkey (Momentive) — Scenario Analysis
A2: Base vs Upside vs Downside — Full Forecast Comparison (2026F)
A4: Metric
A5: REVENUE | B5: Downside | C5: Base Case | D5: Upside | E5: Gap (Up vs Down)
A6: Total Revenue 2023E ($M) | B6: 492.35494 | C6: 523.55156 | D6: 552.65406 | E6: =D6-B6 -> 60.29912
A7: Total Revenue 2026F ($M) | B7: 583.49424 | C7: 745.86545 | D7: 932.63989 | E7: =D7-B7 -> 349.14565
A8: Revenue CAGR 2022- 2026 | B8: 0.11642036 | C8: 0.18709022 | D8: 0.25529876 | E8: =D8-B8 -> 0.1388784
A9: SA Revenue 2026F ($M) | B9: 367.7409 | C9: 469.86217 | D9: 595.43745 | E9: =D9-B9 -> 227.69655
A10: SS Revenue 2026F($M) | B10: 215.75334 | C10: 276.00328 | D10: 337.20244 | E10: =D10-B10 -> 121.4491
A11: SA % of Total Revenue 2026F | B11: =B9/B7 -> 0.63023913 | C11: =C9/C7 -> 0.62995567 | D11: =D9/D7 -> 0.63844305 | E11: =D11-B11 -> 0.0082039166
A13: PROFITABILITY | B13: Downside | C13: Base Case | D13: Upside | E13: Gap (Up vs Down)
A14: Gross Profit 2026F ($M) | B14: 458.04298 | C14: 630.25631 | D14: 797.40711 | E14: =D14-B14 -> 339.36413
A15: Gross Margin % 2026F | B15: 0.785 | C15: 0.845 | D15: 0.855 | E15: =D15-B15 -> 0.07
A16: Operating Income 2026F ($M) | B16: -175.04827 | C16: 11.187982 | D16: 79.274391 | E16: =D16-B16 -> 254.32266
A17: Operating Margin % 2026F | B17: -0.3 | C17: 0.015 | D17: 0.085 | E17: =D17-B17 -> 0.385
A18: Breakeven Achieved? | B18: NO | C18: YES | D18: YES | E18: -
A19: Totall OpEx 2026F ($M) | B19: 633.09125 | C19: 619.06833 | D19: 718.13272 | E19: =D19-B19 -> 85.041465
A21: CUSTOMERS | B21: Downside | C21: Base Case | D21: Upside | E21: Gap (Up vs Down)
A22: SA Ending Customers 2026F | B22: 27171.365 | C22: 32122.351 | D22: 37720.973 | E22: =D22-B22 -> 10549.608
A23: SA Customer CAGR 2022-2026 | B23: 0.34919399 | C23: 0.40685186 | D23: 0.46450972 | E23: =D23-B23 -> 0.11531573
A24: SA Revenue Per Customer 2026F | B24: 13534.135 | C24: 14627.266 | D24: 15785.315 | E24: =D24-B24 -> 2251.1808
A25: SS Ending Users 2026F | B25: 681203.47 | C25: 772417.98 | D25: 872500 | E25: =D25-B25 -> 191296.53
A26: SS Userr Change vs 2022 | B26: -0.17108364 | C26: -0.060090075 | D26: 0.061693843 | E26: =D26-B26 -> 0.23277748
A27: SS Revenue per User 2026F($) | B27: 316.72378 | C27: 357.32374 | D27: 386.47844 | E27: =D27-B27 -> 69.754658
A29: KEY METRICS | B29: Downside | C29: Base Case | D29: Upside | E29: Gap (Up vs Down)
A30: SA Revenue Growth 2022-2026 | B30: 2.4081641 | C30: 3.3546077 | D30: 4.5184194 | E30: =D30-B30 -> 2.1102553
A31: SS Revenue Change 2022-2026 | B31: -0.19404804 | C31: 0.031017104 | D31: 0.25962809 | E31: =D31-B31 -> 0.45367613
A32: Total Revenue Growth 2022-2026 | B32: 0.55349905 | C32: 0.98579727 | D32: 1.4830668 | E32: =D32-B32 -> 0.92956776
A33: Gross Margin Improvement vs 2022-2026 | B33: 0.010785053 | C33: 0.088042509 | D33: 0.10091875 | E33: =D33-B33 -> 0.090133699
A35: STRATEGIC RECOMMENDATION
A36: The Base scenario projects SurveyMonkey reaching operating breakeven in 2026 at $745.9M revenue — a 55% increase from 2022 driven almost entirely by Sales-Assisted growth of 159%. The Upside scenario demonstrates that aggressive enterprise execution and PE-backed investment efficiency could deliver $79.3M operating income by 2026. The Downside scenario highlights the existential risk of enterprise sales underperformance — at -30% operating margin the business burns $175M annually, threatening long-term viability. Across all scenarios Sales-Assisted revenue represents 63-64% of total revenue by 2026, confirming the strategic pivot away from self-serve is irreversible. The critical variable is enterprise customer retention — a 5% improvement in churn rate is worth approximately $60M in additional 2026 revenue.

Sheet Insights
A1: SurveyMonkey (Momentive) — Analyst Insights & Commentary
A2: Based on SEC 10-K filings (2020-2022) and driver-based forecast (2023-2026)
A4: 1. BUSINESS MODEL OVERVIEW
A5: SurveyMonkey operates a two-segment revenue model — self-serve and sales-assisted — that are fundamentally different businesses running in parallel. Self-serve generates high-volume, low-ARPU revenue from individuals and small teams who sign up online without sales interaction. Sales-assisted generates low-volume, high-ARPU revenue from enterprise customers sold to by a dedicated sales force. In 2022 self-serve generated $299.6M from 872,500 users at $344 ARPU while sales-assisted generated $181.3M from just 14,500 customers at $12,503 ARPU — a 36x difference in revenue per customer. This asymmetry is the defining feature of the business and the primary driver of all strategic decisions.
A7: 2. THE STRATEGIC PIVOT
A8: Management made a deliberate decision to redirect investment from self-serve to sales-assisted beginning in 2021. The evidence is clear in the data — self-serve revenue grew 12.5% in 2021 then declined -0.5% in 2022 despite total paying users remaining essentially flat at 887,000. Meanwhile sales-assisted grew 32.3% in 2021 and 27.1% in 2022, adding 6,300 net enterprise customers over two years. This pivot is financially rational — winning one enterprise customer at $12,503 ARPU requires the same operational effort as acquiring 36 self-serve users at $344 ARPU. The acquisition by Symphony Technology Group in 2023 for $1.5B validates this strategy, as PE investors typically accelerate exactly this kind of high-margin enterprise transition.
A10: 3. THE PROFITABILITY CHALLENGE
A11: Despite generating 82% gross margins — exceptional by any standard — SurveyMonkey remained loss-making through 2022 with a -16.9% operating margin. The culprit is Sales & Marketing spend running at 46.5% of revenue in 2022, reflecting the high cost of enterprise customer acquisition. This is a deliberate growth investment — the company is spending today to acquire enterprise customers whose lifetime value justifies the upfront cost. R&D at 28.7% represents continued platform investment to support the enterprise product roadmap. The path to profitability requires either revenue scaling faster than the cost base — operating leverage — or deliberate cost ratio reduction as the enterprise customer base matures. Our Base scenario models both, projecting operating breakeven in 2026 at $745.9M revenue.
A13: 4. SCENARIO ANALYSIS — KEY FINDINGS
A14: Three scenarios were modeled using mathematically derived assumptions grounded in historical SEC filing data. In the Base scenario the business reaches operating breakeven in 2026 generating $11.2M operating income on $745.9M revenue — a 55% increase from 2022 driven by 159% Sales-Assisted revenue growth. In the Upside scenario accelerated enterprise execution and PE-backed cost discipline delivers $79.3M operating income by 2026 with an 8.5% operating margin. In the Downside scenario enterprise sales underperformance and post-acquisition cost pressure produces a -30% operating margin in 2026 with $175M annual cash burn — a financially unsustainable position requiring either external capital or strategic restructuring. The $349M revenue gap between Upside and Downside in 2026 illustrates the binary nature of enterprise SaaS growth — execution quality determines everything.
A16: 5. SELF-SERVE DECLINE — RISK OR TRANSITION?
A17: Self-serve revenue is projected to decline from $299.6M in 2022 to $276.0M in 2026 at Base — a -7.9% cumulative decline over four years. This appears alarming in isolation but must be understood in strategic context. Management is deliberately reducing investment in self-serve customer acquisition as capital is redeployed to enterprise sales. The 872,500 self-serve users represent a stable installed base generating predictable recurring revenue — even in decline this segment contributes meaningfully to covering fixed costs. The risk scenario is not gentle decline but accelerated churn if competitors like Typeform, Google Forms, or Microsoft Forms aggressively price to capture defecting self-serve users. Our Downside scenario models this at -6% annual user decline producing $215.8M self-serve revenue by 2026 — a -28% cumulative decline that would materially impair the overall business case.
... A23: SEC Form 10-K Annual Reports: Fiscal Years 2020, 2021, 2022 — Momentive Global Inc. (formerly SurveyMonkey). Earnings releases and investor presentations: Q4 2020, Q4 2021, Q4 2022. SaaS industry benchmarks: OpenView Partners SaaS Benchmarks Report, KeyBanc Capital Markets SaaS Survey. Acquisition data: Symphony Technology Group press release, September 2023. All derived metrics calculated by analyst from verified source data.
