Workbook

Sheet ACTUALS
A1: TJX CANADA — HISTORICAL PERFORMANCE ACTUALS (FY2021-FY2025)
A3: Metric | B3: FY2021 | C3: FY2022 | D3: FY2023 | E3: FY2024 | F3: FY2025 | G3: Source | H3: % 2025 of total count
A5: STORE COUNT
A6: Winners Stores | B6: 240 | C6: 244 | D6: 248 | E6: 253 | F6: 258 | G6: TJX 10-K | H6: =F6/$F$9 -> 0.53862213
A7: HomeSense Stores | B7: 99 | C7: 101 | D7: 104 | E7: 107 | F7: 110 | G7: TJX 10-K | H7: =F7/$F$9 -> 0.22964509
A8: Marshalls Stores | B8: 97 | C8: 100 | D8: 103 | E8: 107 | F8: 111 | G8: TJX 10-K | H8: =F8/$F$9 -> 0.23173278
A9: Total Stores | B9: =B6+B7+B8 -> 436 | C9: =C6+C7+C8 -> 445 | D9: =D6+D7+D8 -> 455 | E9: =E6+E7+E8 -> 467 | F9: =F6+F7+F8 -> 479 | G9: Formula
A10: Net New Stores | B10: 7 | C10: =C9-B9 -> 9 | D10: =D9-C9 -> 10 | E10: =E9-D9 -> 12 | F10: =F9-E9 -> 12 | G10: Formula
A12: REVENUE
A13: Net Sales | B13: =3510*1000000 -> 3510000000 | C13: =4090*1000000 -> 4090000000 | D13: =4440*1000000 -> 4440000000 | E13: =4710*1000000 -> 4710000000 | F13: =4960*1000000 -> 4960000000 | G13: TJX 10-K
A14: YoY Revenue Growth % | B14: - | C14: =((C13-B13)/B13) -> 0.16524217 | D14: =((D13-C13)/C13) -> 0.085574572 | E14: =((E13-D13)/D13) -> 0.060810811 | F14: =((F13-E13)/E13) -> 0.053078556 | G14: Formula
A15: SSSG % | B15: -0.04 | C15: 0.13 | D15: 0.05 | E15: 0.03 | F15: 0.02 | G15: TJX Earnings
A17: STORE PRODUCTIVITY
A18: Revenue per Store | B18: =B13/B9 -> 8050458.7 | C18: =C13/C9 -> 9191011.2 | D18: =D13/D9 -> 9758241.8 | E18: =E13/E9 -> 10085653 | F18: =F13/F9 -> 10354906 | G18: Formula
A19: Revenue per Store Growth % | B19: - | C19: =((C18-B18)/B18) -> 0.14167547 | D19: =((D18-C18)/C18) -> 0.06171579 | E19: =((E18-D18)/D18) -> 0.033552289 | F19: =((F18-E18)/E18) -> 0.02669663 | G19: Formula
A21: COST OF GOODS SOLD
A22: Cost of Sales | B22: =B13-B27 -> 2495610000 | C22: =C13-C27 -> 2858910000 | D22: =D13-D27 -> 3068040000 | E22: =E13-E27 -> 3249900000 | F22: =F13-F27 -> 3422400000 | G22: Formula
A23: Cost of Sales % | B23: =B22/B13 -> 0.711 | C23: =C22/C13 -> 0.699 | D23: =D22/D13 -> 0.691 | E23: =E22/E13 -> 0.69 | F23: =F22/F13 -> 0.69 | G23: Formula
A25: GROSS MARGIN
A26: Gross Margin % | B26: 0.289 | C26: 0.301 | D26: 0.309 | E26: 0.31 | F26: 0.31 | G26: TJX 10-K
A27: Gross Profit | B27: =B26*B13 -> 1.01439e+09 | C27: =C26*C13 -> 1231090000 | D27: =D26*D13 -> 1371960000 | E27: =E26*E13 -> 1460100000 | F27: =F26*F13 -> 1537600000 | G27: Formula
A29: OPERATING COSTS (% of Sales)
A30: Payroll % | B30: 0.134 | C30: 0.131 | D30: 0.128 | E30: 0.127 | F30: 0.127 | G30: Industry Benchmark
A31: Occupancy % | B31: 0.085 | C31: 0.083 | D31: 0.081 | E31: 0.08 | F31: 0.08 | G31: Industry Benchmark
A32: SG&A % | B32: 0.142 | C32: 0.138 | D32: 0.135 | E32: 0.132 | F32: 0.13 | G32: TJX 10-K
A34: PROFITABILITY
A35: Segment Profit Margin % | B35: 0.155 | C35: 0.161 | D35: 0.161 | E35: 0.149 | F35: 0.135 | G35: TJX 10-K
A36: Operating Income | B36: =B13*B35 -> 544050000 | C36: =C13*C35 -> 658490000 | D36: =D13*D35 -> 714840000 | E36: =E13*E35 -> 701790000 | F36: =F13*F35 -> 669600000 | G36: Formula
A37: YoY OI Growth % | B37: - | C37: =((C36-B36)/B36) -> 0.21034831 | D37: =((D36-C36)/C36) -> 0.085574572 | E37: =((E36-D36)/D36) -> -0.018255833 | F37: =((F36-E36)/E36) -> -0.045868422 | G37: Formula
A39: NEW STORE ECONOMICS
A40: Revenue per Store | B40: =B13/B9 -> 8050458.7 | C40: =C13/C9 -> 9191011.2 | D40: =D13/D9 -> 9758241.8 | E40: =E13/E9 -> 10085653 | F40: =F13/F9 -> 10354906 | G40: Formula
A41: Build-Out Cost per Store | B41: =2.5*1000000 -> 2500000 | C41: =2.5*1000000 -> 2500000 | D41: =2.8*1000000 -> 2800000 | E41: =3*1000000 -> 3000000 | F41: =3*1000000 -> 3000000 | G41: Industry Est.
A42: Inventory per Store | B42: =1*1000000 -> 1000000 | C42: =1*1000000 -> 1000000 | D42: =1.1*1000000 -> 1100000 | E42: =1.2*1000000 -> 1200000 | F42: =1.2*1000000 -> 1200000 | G42: Industry Est.
A43: Total Investment per Store | B43: =B41+B42 -> 3500000 | C43: =C41+C42 -> 3500000 | D43: =D41+D42 -> 3900000 | E43: =E41+E42 -> 4200000 | F43: =F41+F42 -> 4200000 | G43: Formula

Sheet ASSUMPTIONS
A1: TJX CANADA — MODEL ASSUMPTIONS (BEAR / BASE / BULL)
A3: Assumption | B3: Bear | C3: Base | D3: Bull | E3: Derivation | G3: Revenue Growth Per Store
A5: REVENUE ASSUMPTIONS | G5: FY 2026 | H5: FY 2027 | I5: FY 2028
A6: SSSG % | B6: 0.01 | C6: 0.03 | D6: 0.05 | E6: Bear=below mgmt guidance / Base=historical avg FY23-25 / Bull=strong consumer recovery | G6: =ACTUALS!F40*(1+AVERAGE(ACTUALS!$D$19:$F$19)) -> 10775884 | H6: =G6*(1+AVERAGE(ACTUALS!$D$19:$F$19)) -> 11213976 | I6: =H6*(1+AVERAGE(ACTUALS!$D$19:$F$19)) -> 11669879
A7: Winners Revenue per Store | B7: =C7*(1-$B$6) -> 5521607.7 | C7: =ACTUALS!H6*ACTUALS!$F$18 -> 5577381.5 | D7: =C7*(1+$D$6) -> 5856250.6 | E7: Base=FY2025 actual grown by SSSG / Bear and Bull adjusted accordingly
A8: HomeSense Revenue per Store | B8: =C8*(1-$B$6) -> 2354173.8 | C8: =ACTUALS!H7*ACTUALS!$F$18 -> 2377953.4 | D8: =C8*(1+$D$6) -> 2496851 | E8: Base=FY2025 actual grown by SSSG
A9: Marshalls Revenue per Store | B9: =C9*(1-$B$6) -> 2375575.4 | C9: =ACTUALS!H8*ACTUALS!$F$18 -> 2399571.1 | D9: =C9*(1+$D$6) -> 2519549.7 | E9: Base=FY2025 actual grown by SSSG
A10: Annual Revenue per Store Growth % | B10: 0.015 | C10: 0.03 | D10: 0.045 | E10: Driven by SSSG + price mix improvement
A12: STORE EXPANSION ASSUMPTIONS
A13: New Winners Stores per Year | B13: 3 | C13: 5 | D13: 7 | E13: Base=TJX mgmt guidance / Bear=conservative / Bull=aggressive
A14: New HomeSense Stores per Year | B14: 2 | C14: 4 | D14: 5 | E14: Base=TJX mgmt guidance
A15: New Marshalls Stores per Year | B15: 2 | C15: 3 | D15: 4 | E15: Base=TJX mgmt guidance
A16: Total New Stores per Year | B16: 7 | C16: 12 | D16: 16 | E16: Bear=cautious expansion / Base=mgmt plan / Bull=accelerated
A17: Year 1 Ramp (% of mature revenue) | B17: 0.55 | C17: 0.6 | D17: 0.65 | E17: Industry standard off-price retail ramp curve
A18: Year 2 Ramp (% of mature revenue) | B18: 0.75 | C18: 0.8 | D18: 0.85 | E18: Approaching maturity
A19: Year 3 Ramp (% of mature revenue) | B19: 0.9 | C19: 0.95 | D19: 1 | E19: Reaching full productivity
A20: Year 4+ Ramp (% of mature revenue) | B20: 1 | C20: 1 | D20: 1 | E20: Fully mature store
A22: GROSS MARGIN ASSUMPTIONS
A23: Merchandise Margin % | B23: 0.435 | C23: 0.448 | D23: 0.46 | E23: Bear=buying pressure / Base=FY2025 actual / Bull=improved buying conditions
A24: Shrink % of Sales | B24: 0.018 | C24: 0.014 | D24: 0.011 | E24: Bear=theft rising / Base=FY2025 actual / Bull=better loss prevention
A25: Gross Margin % (Net) | B25: 0.295 | C25: 0.31 | D25: 0.325 | E25: Net of merchandise margin shrink and freight
A26: Freight & Distribution % of Sales | B26: 0.022 | C26: 0.02 | D26: 0.018 | E26: Bear=higher freight / Base=current / Bull=optimized supply chain
A27: Buying & Occupancy % of Sales | B27: 0.088 | C27: 0.08 | D27: 0.075 | E27: Bear=higher rents / Base=FY2025 / Bull=renegotiated leases
A29: OPERATING COST ASSUMPTIONS
A30: Payroll % of Sales | B30: 0.115 | C30: 0.108 | D30: 0.102 | E30: Bear=wage inflation / Base=FY2025 benchmark / Bull=productivity gains
A31: G&A % | B31: =C31-0.01 -> 0.057 | C31: 0.067 | D31: =C31+0.01 -> 0.077 | E31: Bear=cost pressure / Base=FY2025 actual / Bull=scale efficiency
A32: Build-Out Cost per New Store | B32: =3.8*1000000 -> 3800000 | C32: =3*1000000 -> 3000000 | D32: =2.8*1000000 -> 2800000 | E32: Bear=construction inflation / Base=FY2025 actual / Bull=standardized build
A33: Inventory per New Store | B33: =1.4*1000000 -> 1400000 | C33: =1.2*1000000 -> 1200000 | D33: =1*1000000 -> 1000000 | E33: Bear=more working capital needed / Base=FY2025 / Bull=lean inventory
A34: Total Investment per New Store | B34: =5.2*1000000 -> 5200000 | C34: =4.2*1000000 -> 4200000 | D34: =3.8*1000000 -> 3800000 | E34: Build-Out + Inventory combined
A35: Payback Period (years) | B35: 6.5 | C35: 4.8 | D35: 3.5 | E35: Total Investment ÷ Annual Operating Income per store
A37: Annual Store Closure
B38: 5 | C38: 3 | D38: 1
A40: Store sqft
B41: 24000 | C41: 24000 | D41: 24000
A43: SCENARIO TOGGLE
A44: Active Scenario | B44: Base
A45: SSSG % | B45: =IF($B$44="Bear",B6,IF($B$44="Base",C6,D6)) -> 0.03
A46: Winners Revenue per Store | B46: =IF($B$44="Bear",B7,IF($B$44="Base",C7,D7)) -> 5577381.5
A47: HomeSense Revenue per Store | B47: =IF($B$44="Bear",B8,IF($B$44="Base",C8,D8)) -> 2377953.4
A48: Marshalls Revenue per Store | B48: =IF($B$44="Bear",B9,IF($B$44="Base",C9,D9)) -> 2399571.1
...

Sheet STORE PLAN
A1: TJX CANADA — STORE EXPANSION PLAN & CAPITAL INVESTMENT | E1: Active Scenario
E2: =ASSUMPTIONS!B44 -> Base
A4: Metric | B4: FY2026F | C4: FY2027F | D4: FY2028F | E4: 3-Year Total
A6: STORE OPENINGS BY BANNER
A7: New Winners Stores | B7: =ASSUMPTIONS!B50 -> 5 | C7: =B7 -> 5 | D7: =C7 -> 5 | E7: =B7+C7+D7 -> 15
A8: New HomeSense Stores | B8: =ASSUMPTIONS!B51 -> 4 | C8: =B8 -> 4 | D8: =C8 -> 4 | E8: =B8+C8+D8 -> 12
A9: New Marshalls Stores | B9: =ASSUMPTIONS!B52 -> 3 | C9: =B9 -> 3 | D9: =C9 -> 3 | E9: =B9+C9+D9 -> 9
A10: Total New Stores | B10: =B7+B8+B9 -> 12 | C10: =C7+C8+C9 -> 12 | D10: =D7+D8+D9 -> 12 | E10: =B10+C10+D10 -> 36
A12: CUMULATIVE STORE COUNT
A13: Winners Total Stores | B13: =ACTUALS!F6+B7 -> 263 | C13: =B13+C7 -> 268 | D13: =C13+D7 -> 273
A14: HomeSense Total Stores | B14: =ACTUALS!F7+B8 -> 114 | C14: =B14+C8 -> 118 | D14: =C14+D8 -> 122
A15: Marshalls Total Stores | B15: =ACTUALS!F8+B9 -> 114 | C15: =B15+C9 -> 117 | D15: =C15+D9 -> 120
A16: Total Stores | B16: =ACTUALS!F9+B10 -> 491 | C16: =B16+C10 -> 503 | D16: =C16+D10 -> 515
A18: CAPITAL INVESTMENT
A19: Winners Build-Out Cost | B19: =(B7*ASSUMPTIONS!$B$65) -> 15000000 | C19: =(C7*ASSUMPTIONS!$B$65) -> 15000000 | D19: =(D7*ASSUMPTIONS!$B$65) -> 15000000 | E19: =B19+C19+D19 -> 45000000
A20: HomeSense Build-Out Cost | B20: =(B8*ASSUMPTIONS!$B$65) -> 12000000 | C20: =(C8*ASSUMPTIONS!$B$65) -> 12000000 | D20: =(D8*ASSUMPTIONS!$B$65) -> 12000000 | E20: =B20+C20+D20 -> 36000000
A21: Marshalls Build-Out Cost | B21: =(B9*ASSUMPTIONS!$B$65) -> 9000000 | C21: =(C9*ASSUMPTIONS!$B$65) -> 9000000 | D21: =(D9*ASSUMPTIONS!$B$65) -> 9000000 | E21: =B21+C21+D21 -> 27000000
A22: Total Build-Out Cost | B22: =((B19+B20+B21)) -> 36000000 | C22: =((C19+C20+C21)) -> 36000000 | D22: =((D19+D20+D21)) -> 36000000 | E22: =((E19+E20+E21)) -> 108000000
A23: Total Inventory Investment | B23: =(B10*ASSUMPTIONS!$B$66) -> 14400000 | C23: =(C10*ASSUMPTIONS!$B$66) -> 14400000 | D23: =(D10*ASSUMPTIONS!$B$66) -> 14400000 | E23: =B23+C23+D23 -> 43200000
A24: TOTAL CAPITAL REQUIRED | B24: =B22+B23 -> 50400000 | C24: =C22+C23 -> 50400000 | D24: =D22+D23 -> 50400000 | E24: =B24+C24+D24 -> 151200000
A26: NEW STORE REVENUE RAMP
A27: Year 1 Revenue | B27: =REVENUE!C14 -> 77586363 | C27: =REVENUE!D14 -> 80740629 | D27: =REVENUE!E14 -> 84023132
A28: Year 2 Revenue | B28: =REVENUE!C15 -> 1.0344848e+08 | C28: =REVENUE!D15 -> 1.0765417e+08 | D28: =REVENUE!E15 -> 1.1203084e+08
A29: Year 3 Revenue | B29: =REVENUE!C16 -> 1.023709e+08 | C29: =REVENUE!D16 -> 1.2783933e+08 | D29: =REVENUE!E16 -> 1.3303662e+08
A30: Year 4 Revenue | B30: =REVENUE!C17 -> 96982954 | C30: =REVENUE!D17 -> 1.1213976e+08 | D30: =REVENUE!E17 -> 1.4003855e+08
A31: TOTAL NEW STORE REVENUE | B31: =SUM(B27:B30) -> 3.803887e+08 | C31: =SUM(C27:C30) -> 4.2837389e+08 | D31: =SUM(D27:D30) -> 4.6912915e+08
A33: STORE CLOSURES
A34: Winners Closures per Year | B34: -1 | C34: -1 | D34: -1
A35: HomeSense Closures per Year | B35: -1 | C35: -1 | D35: -1
A36: Marshalls Closures per Year | B36: -1 | C36: -1 | D36: -1
A37: Total Store Closures | B37: =SUM(B34:B36) -> -3 | C37: =SUM(C34:C36) -> -3 | D37: =SUM(D34:D36) -> -3
A39: NET NEW STORES
A40: Winners Total Stores | B40: =B13+B34 -> 262 | C40: =C13+C34 -> 267 | D40: =D13+D34 -> 272
A41: HomeSense Total Stores | B41: =B14+B35 -> 113 | C41: =C14+C35 -> 117 | D41: =D14+D35 -> 121
A42: Marshalls Total Stores | B42: =B15+B36 -> 113 | C42: =C15+C36 -> 116 | D42: =D15+D36 -> 119
A43: NET Total Stores | B43: =SUM(B40:B42) -> 488 | C43: =SUM(C40:C42) -> 500 | D43: =SUM(D40:D42) -> 512

Sheet REVENUE
A1: TJX CANADA — REVENUE FORECAST FY2026-FY2028 (BASE SCENARIO) | E1: Active Scenario | H1: Memo: FY2025A reflects mature store base only.
E2: =ASSUMPTIONS!B44 -> Base | H2: Ramping stores (FY2023-2025 cohorts) captured in New Store Revenue.
H3: Total reconciles to reported $4.96B net sales.
A4: Revenue Driver | B4: FY2025A | C4: FY2026F | D4: FY2027F | E4: FY2028F | F4: 3-Year Growth
A6: EXISTING STORE REVENUE
A7: Winners — Existing Store Revenue | B7: =(ACTUALS!C6-(ACTUALS!C$10/3))*ACTUALS!$F$18 -> 2.4955324e+09 | C7: =(ACTUALS!D6-(ACTUALS!D$10/3))*ASSUMPTIONS!$G$6 -> 2.6364996e+09 | D7: =(ACTUALS!E6-(ACTUALS!E$10/3))*ASSUMPTIONS!$H$6 -> 2.7922801e+09 | E7: =(ACTUALS!F6-(ACTUALS!F$10/3))*ASSUMPTIONS!$I$6 -> 2.9641494e+09 | F7: =E7 -> 2.9641494e+09
A8: HomeSense — Existing Store Revenue | B8: =(ACTUALS!C7-(ACTUALS!C$10/3))*ACTUALS!$F$18 -> 1.0147808e+09 | C8: =(ACTUALS!D7-(ACTUALS!D$10/3))*ASSUMPTIONS!$G$6 -> 1.0847723e+09 | D8: =(ACTUALS!E7-(ACTUALS!E$10/3))*ASSUMPTIONS!$H$6 -> 1.1550396e+09 | E8: =(ACTUALS!F7-(ACTUALS!F$10/3))*ASSUMPTIONS!$I$6 -> 1.2370072e+09 | F8: =E8 -> 1.2370072e+09
A9: Marshalls — Existing Store Revenue | B9: =(ACTUALS!C8-(ACTUALS!C$10/3))*ACTUALS!$F$18 -> 1.0044259e+09 | C9: =(ACTUALS!D8-(ACTUALS!D$10/3))*ASSUMPTIONS!$G$6 -> 1.0739964e+09 | D9: =(ACTUALS!E8-(ACTUALS!E$10/3))*ASSUMPTIONS!$H$6 -> 1.1550396e+09 | E9: =(ACTUALS!F8-(ACTUALS!F$10/3))*ASSUMPTIONS!$I$6 -> 1.2486771e+09 | F9: =E9 -> 1.2486771e+09
A10: Total Existing Store Revenue | B10: =SUM(B7:B9) -> 4.514739e+09 | C10: =SUM(C7:C9) -> 4.7952683e+09 | D10: =SUM(D7:D9) -> 5.1023592e+09 | E10: =SUM(E7:E9) -> 5.4498337e+09 | F10: =E10 -> 5.4498337e+09
A11: YoY Existing Store Growth % | B11: - | C11: =((C10-B10)/B10) -> 0.062136312 | D11: =((D10-C10)/C10) -> 0.064040407 | E11: =((E10-D10)/D10) -> 0.068100747 | F11: =((E10-B10)/B10) -> 0.20712042
A13: NEW STORE REVENUE
A14: Year 1 Revenue | B14: =(ACTUALS!F18*ACTUALS!F10)*ASSUMPTIONS!B54 -> 74555324 | C14: =(ASSUMPTIONS!G6*'STORE PLAN'!B10)*ASSUMPTIONS!B54 -> 77586363 | D14: =(('STORE PLAN'!C10*ASSUMPTIONS!H6)*ASSUMPTIONS!B54) -> 80740629 | E14: =('STORE PLAN'!D10*ASSUMPTIONS!I6)*ASSUMPTIONS!B54 -> 84023132
A15: Year 2 Revenue | B15: =(ACTUALS!D10*ACTUALS!F18)*ASSUMPTIONS!B55 -> 82839248 | C15: =(ACTUALS!F10*ASSUMPTIONS!G6)*ASSUMPTIONS!B55 -> 1.0344848e+08 | D15: =(ASSUMPTIONS!H6*'STORE PLAN'!B10)*ASSUMPTIONS!B55 -> 1.0765417e+08 | E15: =(('STORE PLAN'!C10*ASSUMPTIONS!I6)*ASSUMPTIONS!B55) -> 1.1203084e+08
A16: Year 3 Revenue | B16: =(ACTUALS!C10*ACTUALS!F18)*ASSUMPTIONS!B56 -> 88534447 | C16: =(ACTUALS!D10*ASSUMPTIONS!G6)*ASSUMPTIONS!B56 -> 1.023709e+08 | D16: =(ACTUALS!F10*ASSUMPTIONS!H6)*ASSUMPTIONS!B56 -> 1.2783933e+08 | E16: =(ASSUMPTIONS!I6*'STORE PLAN'!B10)*ASSUMPTIONS!B56 -> 1.3303662e+08
A17: Year 4 Revenue | B17: =(ACTUALS!B10*ACTUALS!F18)*ASSUMPTIONS!B57 -> 72484342 | C17: =(ACTUALS!C10*ASSUMPTIONS!G6)*ASSUMPTIONS!B57 -> 96982954 | D17: =(ACTUALS!D10*ASSUMPTIONS!H6)*ASSUMPTIONS!B57 -> 1.1213976e+08 | E17: =(ACTUALS!F10*ASSUMPTIONS!I6)*ASSUMPTIONS!B57 -> 1.4003855e+08
A18: Total New Store Revenue | B18: =SUM(B14:B17) -> 3.1841336e+08 | C18: =SUM(C14:C17) -> 3.803887e+08 | D18: =SUM(D14:D17) -> 4.2837389e+08 | E18: =SUM(E14:E17) -> 4.6912915e+08
A20: TOTAL REVENUE SUMMARY
A21: Total Net Sales | B21: =SUM(B10+B18) -> 4.8331524e+09 | C21: =SUM(C10+C18) -> 5.175657e+09 | D21: =SUM(D10+D18) -> 5.5307331e+09 | E21: =SUM(E10+E18) -> 5.9189628e+09
A22: YoY Total Revenue Growth % | B22: - | C22: =((C21-B21)/B21) -> 0.070865667 | D22: =((D21-C21)/C21) -> 0.068605035 | E22: =((E21-D21)/D21) -> 0.070194985
A23: Existing Store Contribution % | B23: =B10/B21 -> 0.93411891 | C23: =C10/C21 -> 0.92650427 | D23: =D10/D21 -> 0.92254663 | E23: =E10/E21 -> 0.92074132
A24: New Store Contribution % | B24: =1-B23 -> 0.065881093 | C24: =1-C23 -> 0.073495732 | D24: =1-D23 -> 0.077453366 | E24: =1-E23 -> 0.079258675
A25: SSSG % | B25: 0.02 | C25: 0.03 | D25: 0.03 | E25: 0.03
A26: Revenue per Store | B26: =ACTUALS!F18 -> 10354906 | C26: =ASSUMPTIONS!G6 -> 10775884 | D26: =ASSUMPTIONS!H6 -> 11213976 | E26: =ASSUMPTIONS!I6 -> 11669879
A27: Total Store Count | B27: =ACTUALS!F9 -> 479 | C27: ='STORE PLAN'!B43 -> 488 | D27: ='STORE PLAN'!C43 -> 500 | E27: ='STORE PLAN'!D43 -> 512
A28: Sales per Square Foot | B28: =B21/(B27*ASSUMPTIONS!$B$70) -> 420.42035 | C28: =C21/(C27*ASSUMPTIONS!$B$70) -> 441.9106 | D28: =D21/(D27*ASSUMPTIONS!$B$70) -> 460.89442 | E28: =E21/(E27*ASSUMPTIONS!$B$70) -> 481.68643

Sheet Profit & Loss
A1: TJX CANADA — FULL P&L FORECAST FY2025A-FY2028F | E1: Active Scenario
E2: =ASSUMPTIONS!B44 -> Base
A4: Line Item | B4: FY2025A | C4: FY2026F | D4: FY2027F | E4: FY2028F | F4: FY25-28 Change
A6: REVENUE
A7: Net Sales | B7: =REVENUE!B21 -> 4.8331524e+09 | C7: =REVENUE!C21 -> 5.175657e+09 | D7: =REVENUE!D21 -> 5.5307331e+09 | E7: =REVENUE!E21 -> 5.9189628e+09 | F7: =E7-B7 -> 1.0858104e+09
A8: YoY Revenue Growth % | B8: - | C8: =((C7-B7)/B7) -> 0.070865667 | D8: =((D7-C7)/C7) -> 0.068605035 | E8: =((E7-D7)/D7) -> 0.070194985
A10: COST OF SALES
A11: Merchandise Cost | B11: =B7*(1-ASSUMPTIONS!$B$58) -> 2.6679001e+09 | C11: =C7*(1-ASSUMPTIONS!$B$58) -> 2.8569626e+09 | D11: =D7*(1-ASSUMPTIONS!$B$58) -> 3.0529647e+09 | E11: =E7*(1-ASSUMPTIONS!$B$58) -> 3.2672675e+09 | F11: =E11-B11 -> 5.9936735e+08
A12: Shrink | B12: =B7*ASSUMPTIONS!$B$59 -> 67664134 | C12: =C7*ASSUMPTIONS!$B$59 -> 72459198 | D12: =D7*ASSUMPTIONS!$B$59 -> 77430263 | E12: =E7*ASSUMPTIONS!$B$59 -> 82865480 | F12: =E12-B12 -> 15201346
A13: Freight & Distribution | B13: =B7*ASSUMPTIONS!$B$61 -> 96663048 | C13: =C7*ASSUMPTIONS!$B$61 -> 1.0351314e+08 | D13: =D7*ASSUMPTIONS!$B$61 -> 1.1061466e+08 | E13: =E7*ASSUMPTIONS!$B$61 -> 1.1837926e+08 | F13: =E13-B13 -> 21716208
A14: Buying & Occupancy | B14: =B7*ASSUMPTIONS!$B$62 -> 3.8665219e+08 | C14: =C7*ASSUMPTIONS!$B$62 -> 4.1405256e+08 | D14: =D7*ASSUMPTIONS!$B$62 -> 4.4245865e+08 | E14: =E7*ASSUMPTIONS!$B$62 -> 4.7351703e+08 | F14: =E14-B14 -> 86864834
A15: Other COGS | B15: =B7*ASSUMPTIONS!$B$73 -> 1.1599566e+08 | C15: =C7*ASSUMPTIONS!$B$73 -> 1.2421577e+08 | D15: =D7*ASSUMPTIONS!$B$73 -> 1.3273759e+08 | E15: =E7*ASSUMPTIONS!$B$73 -> 1.4205511e+08 | F15: =E15-B15 -> 26059450
A16: Total Cost of Sales | B16: =SUM(B11:B15) -> 3.3348752e+09 | C16: =SUM(C11:C15) -> 3.5712033e+09 | D16: =SUM(D11:D15) -> 3.8162058e+09 | E16: =SUM(E11:E15) -> 4.0840843e+09 | F16: =E16-B16 -> 7.4920919e+08
A17: Cost of Sales % of Net Sales | B17: =B16/B7 -> 0.69 | C17: =C16/C7 -> 0.69 | D17: =D16/D7 -> 0.69 | E17: =E16/E7 -> 0.69
A19: GROSS PROFIT
A20: Gross Profit | B20: =B7-B16 -> 1.4982772e+09 | C20: =C7-C16 -> 1.6044537e+09 | D20: =D7-D16 -> 1.7145273e+09 | E20: =E7-E16 -> 1.8348785e+09 | F20: =E20-B20 -> 3.3660123e+08
A21: Gross Margin % | B21: =B20/B7 -> 0.31 | C21: =C20/C7 -> 0.31 | D21: =D20/D7 -> 0.31 | E21: =E20/E7 -> 0.31
A23: OPERATING EXPENSES
A24: Store Payroll & Benefits | B24: ='Profit & Loss'!B7*ASSUMPTIONS!$B$63 -> 5.2198046e+08 | C24: ='Profit & Loss'!C7*ASSUMPTIONS!$B$63 -> 5.5897095e+08 | D24: ='Profit & Loss'!D7*ASSUMPTIONS!$B$63 -> 5.9731917e+08 | E24: ='Profit & Loss'!E7*ASSUMPTIONS!$B$63 -> 6.3924798e+08 | F24: =E24-B24 -> 1.1726753e+08
A25: General & Administrative | B25: =B7*ASSUMPTIONS!$B$64 -> 3.2382121e+08 | C25: =C7*ASSUMPTIONS!$B$64 -> 3.4676902e+08 | D25: =D7*ASSUMPTIONS!$B$64 -> 3.7055912e+08 | E25: =E7*ASSUMPTIONS!$B$64 -> 3.9657051e+08 | F25: =E25-B25 -> 72749298
A26: Total SG&A | B26: =SUM(B24:B25) -> 8.4580167e+08 | C26: =SUM(C24:C25) -> 9.0573997e+08 | D26: =SUM(D24:D25) -> 9.6787829e+08 | E26: =SUM(E24:E25) -> 1.0358185e+09 | F26: =E26-B26 -> 1.9001682e+08
A27: SG&A % of Net Sales | B27: =B26/B7 -> 0.175 | C27: =C26/C7 -> 0.175 | D27: =D26/D7 -> 0.175 | E27: =E26/E7 -> 0.175
A29: OPERATING INCOME
A30: Operating Income | B30: =B20-B26 -> 6.5247557e+08 | C30: =C20-C26 -> 6.9871369e+08 | D30: =D20-D26 -> 7.4664897e+08 | E30: =E20-E26 -> 7.9905998e+08 | F30: =E30-B30 -> 1.4658441e+08
A31: Operating Margin % | B31: =B30/B7 -> 0.135 | C31: =C30/C7 -> 0.135 | D31: =D30/D7 -> 0.135 | E31: =E30/E7 -> 0.135
A32: YoY Operating Income Growth % | B32: - | C32: =((C30-B30)/B30) -> 0.070865667 | D32: =((D30-C30)/C30) -> 0.068605035 | E32: =((E30-D30)/D30) -> 0.070194985
A34: KEY METRICS
A35: Revenue per Store | B35: =ACTUALS!F40 -> 10354906 | C35: =ASSUMPTIONS!G6 -> 10775884 | D35: =ASSUMPTIONS!H6 -> 11213976 | E35: =ASSUMPTIONS!I6 -> 11669879 | F35: =E35-B35 -> 1314973.3
A36: Operating Income per Store | B36: =B30/ACTUALS!F9 -> 1362162 | C36: =C30/'STORE PLAN'!B43 -> 1431790.3 | D36: =D30/'STORE PLAN'!C43 -> 1493297.9 | E36: =E30/'STORE PLAN'!D43 -> 1560664 | F36: =E36-B36 -> 198502.08
A37: Sales per Square Foot | B37: =REVENUE!B28 -> 420.42035 | C37: =REVENUE!C28 -> 441.9106 | D37: =REVENUE!D28 -> 460.89442 | E37: =REVENUE!E28 -> 481.68643 | F37: =E37-B37 -> 61.266073
A38: New Store Contribution to Revenue % | B38: =REVENUE!B24 -> 0.065881093 | C38: =REVENUE!C24 -> 0.073495732 | D38: =REVENUE!D24 -> 0.077453366 | E38: =REVENUE!E24 -> 0.079258675 | F38: =E38-B38 -> 0.013377582
A39: Existing Store Contribution to Revenue % | B39: =1-B38 -> 0.93411891 | C39: =1-C38 -> 0.92650427 | D39: =1-D38 -> 0.92254663 | E39: =1-E38 -> 0.92074132 | F39: =E39-B39 -> -0.013377582

Sheet SCENARIO
A1: TJX CANADA — SCENARIO ANALYSIS FY2028F (3-YEAR OUTLOOK)
A3: Metric | B3: Bear Case | C3: Base Case | D3: Bull Case
A5: KEY ASSUMPTIONS
A6: SSSG % | B6: 0.01 | C6: 0.03 | D6: 0.05
A7: New Stores per Year | B7: 7 | C7: 12 | D7: 16
A8: Merchandise Margin % | B8: 0.435 | C8: 0.448 | D8: 0.46
A9: Gross Margin % | B9: 0.295 | C9: 0.31 | D9: 0.325
A10: Payroll % of Sales | B10: 0.115 | C10: 0.108 | D10: 0.102
A11: Total SG&A % of Sales | B11: 0.19 | C11: 0.175 | D11: 0.16
A13: FY2028 FINANCIAL OUTCOMES
A14: Total Net Sales | B14: 5.7695884e+09 | C14: 5.9189628e+09 | D14: 6.0566674e+09
A15: YoY Revenue CAGR (3-year) | B15: =((B14/REVENUE!B21)^((1/3))-1) -> 0.060811241 | C15: =((C14/REVENUE!$B$21)^((1/3))-1) -> 0.069888142 | D15: =((D14/REVENUE!$B$21)^((1/3))-1) -> 0.078121595
A16: Gross Profit | B16: 1.6327935e+09 | C16: 1.8348785e+09 | D16: 2.0108136e+09
A17: Gross Margin % | B17: 0.283 | C17: 0.31 | D17: 0.332
A18: Operating Income | B18: 6.4042431e+08 | C18: 7.9905998e+08 | D18: 9.2667011e+08
A19: Operating Margin % | B19: 0.111 | C19: 0.135 | D19: 0.153
A20: Operating Income Growth vs FY2025 | B20: =((B18-'Profit & Loss'!$B30)/'Profit & Loss'!$B30) -> -0.018470064 | C20: =((C18-'Profit & Loss'!$B30)/'Profit & Loss'!$B30) -> 0.22465884 | D20: =((D18-'Profit & Loss'!$B30)/'Profit & Loss'!$B30) -> 0.42023725
A22: NEW STORE IMPACT FY2028 (3 years)
A23: Total New Stores Opened | B23: =7*3 -> 21 | C23: =12*3 -> 36 | D23: =16*3 -> 48
A24: New Store Revenue Contribution | B24: 3.2325048e+08 | C24: 5.9507176e+08 | D24: 8.479998e+08
A25: New Store % of Total Revenue | B25: 0.061043069 | C25: 0.070194985 | D25: 0.078043702
A26: Total Capital Invested | B26: =36400000*3 -> 109200000 | C26: =50400000*3 -> 151200000 | D26: =60800000*3 -> 182400000
A27: Return on New Store Investment % | B27: =((B24*13.5%)/B26) -> 0.39962284 | C27: =((C24*13.5%)/C26) -> 0.53131407 | D27: =((D24*16.5%)/D26) -> 0.76710508

Sheet INSIGHTS
A1: TJX CANADA — EXECUTIVE INSIGHT & STORE EXPANSION RECOMMENDATION
A3: Executive Summary
A5: The Base Scenario projects continued profitable growth between FY2026 and FY2028, supported by disciplined store expansion, positive Same Store Sales Growth (SSSG), and stable operating margins. Revenue growth is driven primarily by the existing store network, while new store openings create additional longterm revenue capacity. The model demonstrates that maintaining controlled expansion and effective cost management will be the key drivers of sustainable profitability.
A12: Revenue Insights
A14: Revenue is projected to grow consistently throughout the forecast period under the Base Scenario. Existing stores remain the largest contributor to total sales, highlighting the importance of maintaining positive Same Store Sales Growth (SSSG). New store openings provide incremental revenue while strengthening TJX Canada's long-term market presence. The store ramp-up methodology assumes new stores gradually reach mature sales productivity, creating a more realistic revenue forecast.
A25: Store Expansion
A27: The expansion plan supports sustainable long-term growth while maintaining disciplined capital allocation. New stores increase future revenue capacity without placing excessive pressure on operating performance. A balanced expansion strategy across Winners, Marshalls, and HomeSense reduces concentration risk while supporting market penetration. Gradual store expansion allows management to optimize staffing, inventory management, and operational efficiency.
A36: Profitability Insights
A38: Gross Margin remains stable throughout the forecast period, reflecting the resilience of TJX Canada's off-price retail business model. Operating Income increases as revenue growth outpaces the growth in operating expenses. Operating Margin improves through operating leverage generated by higher sales volumes across the existing and expanding store base. Disciplined SG&A management remains critical to sustaining long-term profitability.
A46: Scenario Analysis
A48: Bear Scenario
A50: Lower consumer demand and weaker Same Store Sales Growth reduce revenue growth and compress operating margins. Profitability remains positive, but expansion generates lower financial returns.
... A81: 5. Continue utilizing scenario planning to evaluate potential changes in consumer demand and support strategic decisionmaking.
